Workbook
Name scen_sel: Inputs!$B$4
Name SCEN_TABLE: Inputs!$A$18:$F$23
Name WAL_A: Scenario_Summary!$G$7
Name YIELD_A: Scenario_Summary!$H$7
Name LOSS_A: Scenario_Summary!$E$7
Name PRINPAID_A: Scenario_Summary!$D$7
Name INTPAID_A: Scenario_Summary!$C$7
Name CF_A: CashFlows!$F$5:$F$101
Name FV_A: Retention!$C$6
Name FVLIVE_A: Retention!$D$6
Name FVLOCK_A: Inputs!$B$81
Name WAL_B: Scenario_Summary!$G$8
Name YIELD_B: Scenario_Summary!$H$8
Name LOSS_B: Scenario_Summary!$E$8
Name PRINPAID_B: Scenario_Summary!$D$8
Name INTPAID_B: Scenario_Summary!$C$8
Name CF_B: CashFlows!$K$5:$K$101
Name FV_B: Retention!$C$7
Name FVLIVE_B: Retention!$D$7
Name FVLOCK_B: Inputs!$B$82
Name WAL_C: Scenario_Summary!$G$9
Name YIELD_C: Scenario_Summary!$H$9
Name LOSS_C: Scenario_Summary!$E$9
Name PRINPAID_C: Scenario_Summary!$D$9
Name INTPAID_C: Scenario_Summary!$C$9
Name CF_C: CashFlows!$P$5:$P$101
Name FV_C: Retention!$C$8
Name FVLIVE_C: Retention!$D$8
Name FVLOCK_C: Inputs!$B$83
Name WAL_R: Scenario_Summary!$G$10
Name YIELD_R: Scenario_Summary!$H$10
Name LOSS_R: Scenario_Summary!$E$10
Name PRINPAID_R: Scenario_Summary!$D$10
Name INTPAID_R: Scenario_Summary!$C$10
Name CF_R: CashFlows!$S$5:$S$101
Name FV_R: Retention!$C$9
Name FVLIVE_R: Retention!$D$9
Name FVLOCK_R: Inputs!$B$84
Name ENDBAL_A: CashFlows!$E$5:$E$101
Name ENDBAL_B: CashFlows!$J$5:$J$101
Name ENDBAL_C: CashFlows!$O$5:$O$101
Name CHECK_POOL_RECON: Scenario_Summary!$B$15
Name CHECK_CASH: Scenario_Summary!$B$16
Name CHECK_NOTES_OVER_CASH: Scenario_Summary!$B$17
Name BREACH_MONTHS: Scenario_Summary!$B$21
Name FRAC_TABLE: Retention!$B$15:$E$19
Name RET_AMOUNTS: Retention!$F$15:$H$19
Name RET_OUT: Retention!$B$28:$I$32
Name INPUT_POOL_BAL: Inputs!$B$49
Name INPUT_BAL_R: Inputs!$B$50
Name RETCF_RRV: Retention_CF!$H$5:$H$101
Name RETCF_RRH: Retention_CF!$M$5:$M$101
Name RETCF_RRL: Retention_CF!$R$5:$R$101
Name RETCF_EUV: Retention_CF!$W$5:$W$101
Name RETCF_EUFL: Retention_CF!$AB$5:$AB$101
Name POOL_END: Pool!$BP$5:$BP$101
Name POOL_CASH: Pool!$BW$5:$BW$101
Name ES_BPS: Tests!$O$5:$O$101
Name IN_SCEN_SEL: Inputs!$B$4
Name IN_POOL_BAL: Inputs!$B$49

Sheet Inputs
A1: Inputs (typed values live only on this sheet). Collateral is SYNTHETIC; forward curve is ASSUMED.
A3: Active scenario
A4: Selected scenario number (1-based row of scenario table) | B4: 1
A5: Pool rep lines (name, balance, WAC, remaining term)
A6: RL01 | B6: 60000000 | C6: 0.065 | D6: 60
A7: RL02 | B7: 55000000 | C7: 0.0725 | D7: 72
A8: RL03 | B8: 50000000 | C8: 0.08 | D8: 48
A9: RL04 | B9: 48000000 | C9: 0.0875 | D9: 66
A10: RL05 | B10: 45000000 | C10: 0.095 | D10: 60
A11: RL06 | B11: 40000000 | C11: 0.1025 | D11: 84
A12: RL07 | B12: 35000000 | C12: 0.11 | D12: 54
A13: RL08 | B13: 30000000 | C13: 0.1175 | D13: 72
A14: RL09 | B14: 22000000 | C14: 0.125 | D14: 36
A15: RL10 | B15: 15000000 | C15: 0.135 | D15: 48
A17: Scenario table (name, CPR, CDR, severity, recovery lag months, forward shift bps)
A18: Base | B18: 0.1 | C18: 0.03 | D18: 0.4 | E18: 6 | F18: 0
A19: Mild stress | B19: 0.1 | C19: 0.06 | D19: 0.5 | E19: 6 | F19: 0
A20: Stress | B20: 0.06 | C20: 0.12 | D20: 0.6 | E20: 9 | F20: 0
A21: Severe stress | B21: 0.04 | C21: 0.2 | D21: 0.7 | E21: 12 | F21: 0
A22: Fast prepay | B22: 0.3 | C22: 0.03 | D22: 0.4 | E22: 6 | F22: 0
A23: Rate shock +300bp | B23: 0.1 | C23: 0.06 | D23: 0.5 | E23: 6 | F23: 300
A25: Active scenario values (formulas)
A26: Scenario name | B26: =INDEX($A$18:$A$23,Inputs!$B$4)
A27: CPR | B27: =INDEX($B$18:$B$23,Inputs!$B$4) | C27: annual
A28: CDR | B28: =INDEX($C$18:$C$23,Inputs!$B$4) | C28: annual
A29: Loss severity | B29: =INDEX($D$18:$D$23,Inputs!$B$4) | C29: of defaulted balance
A30: Recovery lag (months) | B30: =INDEX($E$18:$E$23,Inputs!$B$4)
A31: Forward curve shift (bps) | B31: =INDEX($F$18:$F$23,Inputs!$B$4)
A32: SMM | B32: =1-(1-Inputs!$B$27)^(1/12) | C32: monthly
A33: MDR | B33: =1-(1-Inputs!$B$28)^(1/12) | C33: monthly
A35: Curve, notes, fees, reserve
A36: Forward index at t=0 | B36: 0.043
A37: Forward index long-run | B37: 0.0325
A38: Curve time constant (months) | B38: 24
A39: Class A balance | B39: 300000000
A40: Class B balance | B40: 40000000
A41: Class C balance | B41: 30000000
A42: Class A margin over index | B42: 0.011
A43: Class B margin over index | B43: 0.0225
A44: Class C fixed coupon | B44: 0.075
...

Sheet Pool
A1: Pool
A2: Rep-line amortization. Order: defaults, interest, scheduled principal, prepayment. Period 0 is closing.
A4: Period | B4: Forward index | C4: RL01 beg | D4: RL01 defaults | E4: RL01 interest | F4: RL01 sched prin | G4: RL01 prepay | H4: RL01 end | I4: RL02 beg | J4: RL02 defaults | K4: RL02 interest | L4: RL02 sched prin | M4: RL02 prepay | N4: RL02 end | O4: RL03 beg | P4: RL03 defaults | Q4: RL03 interest | R4: RL03 sched prin | S4: RL03 prepay | T4: RL03 end | U4: RL04 beg | V4: RL04 defaults | W4: RL04 interest | X4: RL04 sched prin | Y4: RL04 prepay | Z4: RL04 end | AA4: RL05 beg | AB4: RL05 defaults | AC4: RL05 interest | AD4: RL05 sched prin | AE4: RL05 prepay | AF4: RL05 end | AG4: RL06 beg | AH4: RL06 defaults | AI4: RL06 interest | AJ4: RL06 sched prin | AK4: RL06 prepay | AL4: RL06 end | AM4: RL07 beg | AN4: RL07 defaults | AO4: RL07 interest | AP4: RL07 sched prin | AQ4: RL07 prepay | AR4: RL07 end | AS4: RL08 beg | AT4: RL08 defaults | AU4: RL08 interest | AV4: RL08 sched prin | AW4: RL08 prepay | AX4: RL08 end | AY4: RL09 beg | AZ4: RL09 defaults | BA4: RL09 interest | BB4: RL09 sched prin | BC4: RL09 prepay | BD4: RL09 end | BE4: RL10 beg | BF4: RL10 defaults | BG4: RL10 interest | BH4: RL10 sched prin | BI4: RL10 prepay | BJ4: RL10 end | BK4: Pool beg balance | BL4: Pool defaults | BM4: Pool interest | BN4: Pool sched principal | BO4: Pool prepayments | BP4: Pool end balance | BQ4: Recoveries | BR4: Cum defaults | BS4: Cum recoveries | BT4: Cum net loss (default x severity) | BU4: Pending recoveries | BV4: Collateral value (end + pending) | BW4: Collateral cash in | BX4: Balance recon (beg-def-sch-pre-end)
A5: 0 | B5: =Inputs!$B$36+(Inputs!$B$37-Inputs!$B$36)*(1-EXP(-A5/Inputs!$B$38))+Inputs!$B$31/10000 | H5: =Inputs!$B$6 | N5: =Inputs!$B$7 | T5: =Inputs!$B$8 | Z5: =Inputs!$B$9 | AF5: =Inputs!$B$10 | AL5: =Inputs!$B$11 | AR5: =Inputs!$B$12 | AX5: =Inputs!$B$13 | BD5: =Inputs!$B$14 | BJ5: =Inputs!$B$15 | BP5: =H5+N5+T5+Z5+AF5+AL5+AR5+AX5+BD5+BJ5 | BR5: 0 | BS5: 0 | BT5: 0 | BU5: 0 | BV5: =BP5+BU5
A6: 1 | B6: =Inputs!$B$36+(Inputs!$B$37-Inputs!$B$36)*(1-EXP(-A6/Inputs!$B$38))+Inputs!$B$31/10000 | C6: =H5 | D6: =C6*Inputs!$B$33 | E6: =(C6-D6)*Inputs!$C$6/12 | F6: =IF(MAX(Inputs!$D$6-(A6-1),0)<=0,0,(C6-D6)*((Inputs!$C$6/12)/(1-(1+Inputs!$C$6/12)^(-MAX(Inputs!$D$6-(A6-1),0)))-Inputs!$C$6/12)) | G6: =(C6-D6-F6)*Inputs!$B$32 | H6: =C6-D6-F6-G6 | I6: =N5 | J6: =I6*Inputs!$B$33 | K6: =(I6-J6)*Inputs!$C$7/12 | L6: =IF(MAX(Inputs!$D$7-(A6-1),0)<=0,0,(I6-J6)*((Inputs!$C$7/12)/(1-(1+Inputs!$C$7/12)^(-MAX(Inputs!$D$7-(A6-1),0)))-Inputs!$C$7/12)) | M6: =(I6-J6-L6)*Inputs!$B$32 | N6: =I6-J6-L6-M6 | O6: =T5 | P6: =O6*Inputs!$B$33 | Q6: =(O6-P6)*Inputs!$C$8/12 | R6: =IF(MAX(Inputs!$D$8-(A6-1),0)<=0,0,(O6-P6)*((Inputs!$C$8/12)/(1-(1+Inputs!$C$8/12)^(-MAX(Inputs!$D$8-(A6-1),0)))-Inputs!$C$8/12)) | S6: =(O6-P6-R6)*Inputs!$B$32 | T6: =O6-P6-R6-S6 | U6: =Z5 | V6: =U6*Inputs!$B$33 | W6: =(U6-V6)*Inputs!$C$9/12 | X6: =IF(MAX(Inputs!$D$9-(A6-1),0)<=0,0,(U6-V6)*((Inputs!$C$9/12)/(1-(1+Inputs!$C$9/12)^(-MAX(Inputs!$D$9-(A6-1),0)))-Inputs!$C$9/12)) | Y6: =(U6-V6-X6)*Inputs!$B$32 | Z6: =U6-V6-X6-Y6 | AA6: =AF5 | AB6: =AA6*Inputs!$B$33 | AC6: =(AA6-AB6)*Inputs!$C$10/12 | AD6: =IF(MAX(Inputs!$D$10-(A6-1),0)<=0,0,(AA6-AB6)*((Inputs!$C$10/12)/(1-(1+Inputs!$C$10/12)^(-MAX(Inputs!$D$10-(A6-1),0)))-Inputs!$C$10/12)) | AE6: =(AA6-AB6-AD6)*Inputs!$B$32 | AF6: =AA6-AB6-AD6-AE6 | AG6: =AL5 | AH6: =AG6*Inputs!$B$33 | AI6: =(AG6-AH6)*Inputs!$C$11/12 | AJ6: =IF(MAX(Inputs!$D$11-(A6-1),0)<=0,0,(AG6-AH6)*((Inputs!$C$11/12)/(1-(1+Inputs!$C$11/12)^(-MAX(Inputs!$D$11-(A6-1),0)))-Inputs!$C$11/12)) | AK6: =(AG6-AH6-AJ6)*Inputs!$B$32 | AL6: =AG6-AH6-AJ6-AK6 | AM6: =AR5 | AN6: =AM6*Inputs!$B$33 | AO6: =(AM6-AN6)*Inputs!$C$12/12 | AP6: =IF(MAX(Inputs!$D$12-(A6-1),0)<=0,0,(AM6-AN6)*((Inputs!$C$12/12)/(1-(1+Inputs!$C$12/12)^(-MAX(Inputs!$D$12-(A6-1),0)))-Inputs!$C$12/12)) | AQ6: =(AM6-AN6-AP6)*Inputs!$B$32 | AR6: =AM6-AN6-AP6-AQ6 | AS6: =AX5 | AT6: =AS6*Inputs!$B$33 | AU6: =(AS6-AT6)*Inputs!$C$13/12 | AV6: =IF(MAX(Inputs!$D$13-(A6-1),0)<=0,0,(AS6-AT6)*((Inputs!$C$13/12)/(1-(1+Inputs!$C$13/12)^(-MAX(Inputs!$D$13-(A6-1),0)))-Inputs!$C$13/12)) | AW6: =(AS6-AT6-AV6)*Inputs!$B$32 | AX6: =AS6-AT6-AV6-AW6 | AY6: =BD5 | AZ6: =AY6*Inputs!$B$33 | BA6: =(AY6-AZ6)*Inputs!$C$14/12 | BB6: =IF(MAX(Inputs!$D$14-(A6-1),0)<=0,0,(AY6-AZ6)*((Inputs!$C$14/12)/(1-(1+Inputs!$C$14/12)^(-MAX(Inputs!$D$14-(A6-1),0)))-Inputs!$C$14/12)) | BC6: =(AY6-AZ6-BB6)*Inputs!$B$32 | BD6: =AY6-AZ6-BB6-BC6 | BE6: =BJ5 | BF6: =BE6*Inputs!$B$33 | BG6: =(BE6-BF6)*Inputs!$C$15/12 | BH6: =IF(MAX(Inputs!$D$15-(A6-1),0)<=0,0,(BE6-BF6)*((Inputs!$C$15/12)/(1-(1+Inputs!$C$15/12)^(-MAX(Inputs!$D$15-(A6-1),0)))-Inputs!$C$15/12)) | BI6: =(BE6-BF6-BH6)*Inputs!$B$32 | BJ6: =BE6-BF6-BH6-BI6 | BK6: =C6+I6+O6+U6+AA6+AG6+AM6+AS6+AY6+BE6 | BL6: =D6+J6+P6+V6+AB6+AH6+AN6+AT6+AZ6+BF6 | BM6: =E6+K6+Q6+W6+AC6+AI6+AO6+AU6+BA6+BG6 | BN6: =F6+L6+R6+X6+AD6+AJ6+AP6+AV6+BB6+BH6 | BO6: =G6+M6+S6+Y6+AE6+AK6+AQ6+AW6+BC6+BI6 | BP6: =H6+N6+T6+Z6+AF6+AL6+AR6+AX6+BD6+BJ6 | BQ6: =IF(A6-Inputs!$B$30>=1,INDEX($BL$5:$BL$101,A6-Inputs!$B$30+1)*(1-Inputs!$B$29),0) | BR6: =BR5+BL6 | BS6: =BS5+BQ6 | BT6: =BR6*Inputs!$B$29 | BU6: =BR6*(1-Inputs!$B$29)-BS6 | BV6: =BP6+BU6 | BW6: =BM6+BN6+BO6+BQ6 | BX6: =BK6-BL6-BN6-BO6-BP6
A7: 2 | B7: =Inputs!$B$36+(Inputs!$B$37-Inputs!$B$36)*(1-EXP(-A7/Inputs!$B$38))+Inputs!$B$31/10000 | C7: =H6 | D7: =C7*Inputs!$B$33 | E7: =(C7-D7)*Inputs!$C$6/12 | F7: =IF(MAX(Inputs!$D$6-(A7-1),0)<=0,0,(C7-D7)*((Inputs!$C$6/12)/(1-(1+Inputs!$C$6/12)^(-MAX(Inputs!$D$6-(A7-1),0)))-Inputs!$C$6/12)) | G7: =(C7-D7-F7)*Inputs!$B$32 | H7: =C7-D7-F7-G7 | I7: =N6 | J7: =I7*Inputs!$B$33 | K7: =(I7-J7)*Inputs!$C$7/12 | L7: =IF(MAX(Inputs!$D$7-(A7-1),0)<=0,0,(I7-J7)*((Inputs!$C$7/12)/(1-(1+Inputs!$C$7/12)^(-MAX(Inputs!$D$7-(A7-1),0)))-Inputs!$C$7/12)) | M7: =(I7-J7-L7)*Inputs!$B$32 | N7: =I7-J7-L7-M7 | O7: =T6 | P7: =O7*Inputs!$B$33 | Q7: =(O7-P7)*Inputs!$C$8/12 | R7: =IF(MAX(Inputs!$D$8-(A7-1),0)<=0,0,(O7-P7)*((Inputs!$C$8/12)/(1-(1+Inputs!$C$8/12)^(-MAX(Inputs!$D$8-(A7-1),0)))-Inputs!$C$8/12)) | S7: =(O7-P7-R7)*Inputs!$B$32 | T7: =O7-P7-R7-S7 | U7: =Z6 | V7: =U7*Inputs!$B$33 | W7: =(U7-V7)*Inputs!$C$9/12 | X7: =IF(MAX(Inputs!$D$9-(A7-1),0)<=0,0,(U7-V7)*((Inputs!$C$9/12)/(1-(1+Inputs!$C$9/12)^(-MAX(Inputs!$D$9-(A7-1),0)))-Inputs!$C$9/12)) | Y7: =(U7-V7-X7)*Inputs!$B$32 | Z7: =U7-V7-X7-Y7 | AA7: =AF6 | AB7: =AA7*Inputs!$B$33 | AC7: =(AA7-AB7)*Inputs!$C$10/12 | AD7: =IF(MAX(Inputs!$D$10-(A7-1),0)<=0,0,(AA7-AB7)*((Inputs!$C$10/12)/(1-(1+Inputs!$C$10/12)^(-MAX(Inputs!$D$10-(A7-1),0)))-Inputs!$C$10/12)) | AE7: =(AA7-AB7-AD7)*Inputs!$B$32 | AF7: =AA7-AB7-AD7-AE7 | AG7: =AL6 | AH7: =AG7*Inputs!$B$33 | AI7: =(AG7-AH7)*Inputs!$C$11/12 | AJ7: =IF(MAX(Inputs!$D$11-(A7-1),0)<=0,0,(AG7-AH7)*((Inputs!$C$11/12)/(1-(1+Inputs!$C$11/12)^(-MAX(Inputs!$D$11-(A7-1),0)))-Inputs!$C$11/12)) | AK7: =(AG7-AH7-AJ7)*Inputs!$B$32 | AL7: =AG7-AH7-AJ7-AK7 | AM7: =AR6 | AN7: =AM7*Inputs!$B$33 | AO7: =(AM7-AN7)*Inputs!$C$12/12 | AP7: =IF(MAX(Inputs!$D$12-(A7-1),0)<=0,0,(AM7-AN7)*((Inputs!$C$12/12)/(1-(1+Inputs!$C$12/12)^(-MAX(Inputs!$D$12-(A7-1),0)))-Inputs!$C$12/12)) | AQ7: =(AM7-AN7-AP7)*Inputs!$B$32 | AR7: =AM7-AN7-AP7-AQ7 | AS7: =AX6 | AT7: =AS7*Inputs!$B$33 | AU7: =(AS7-AT7)*Inputs!$C$13/12 | AV7: =IF(MAX(Inputs!$D$13-(A7-1),0)<=0,0,(AS7-AT7)*((Inputs!$C$13/12)/(1-(1+Inputs!$C$13/12)^(-MAX(Inputs!$D$13-(A7-1),0)))-Inputs!$C$13/12)) | AW7: =(AS7-AT7-AV7)*Inputs!$B$32 | AX7: =AS7-AT7-AV7-AW7 | AY7: =BD6 | AZ7: =AY7*Inputs!$B$33 | BA7: =(AY7-AZ7)*Inputs!$C$14/12 | BB7: =IF(MAX(Inputs!$D$14-(A7-1),0)<=0,0,(AY7-AZ7)*((Inputs!$C$14/12)/(1-(1+Inputs!$C$14/12)^(-MAX(Inputs!$D$14-(A7-1),0)))-Inputs!$C$14/12)) | BC7: =(AY7-AZ7-BB7)*Inputs!$B$32 | BD7: =AY7-AZ7-BB7-BC7 | BE7: =BJ6 | BF7: =BE7*Inputs!$B$33 | BG7: =(BE7-BF7)*Inputs!$C$15/12 | BH7: =IF(MAX(Inputs!$D$15-(A7-1),0)<=0,0,(BE7-BF7)*((Inputs!$C$15/12)/(1-(1+Inputs!$C$15/12)^(-MAX(Inputs!$D$15-(A7-1),0)))-Inputs!$C$15/12)) | BI7: =(BE7-BF7-BH7)*Inputs!$B$32 | BJ7: =BE7-BF7-BH7-BI7 | BK7: =C7+I7+O7+U7+AA7+AG7+AM7+AS7+AY7+BE7 | BL7: =D7+J7+P7+V7+AB7+AH7+AN7+AT7+AZ7+BF7 | BM7: =E7+K7+Q7+W7+AC7+AI7+AO7+AU7+BA7+BG7 | BN7: =F7+L7+R7+X7+AD7+AJ7+AP7+AV7+BB7+BH7 | BO7: =G7+M7+S7+Y7+AE7+AK7+AQ7+AW7+BC7+BI7 | BP7: =H7+N7+T7+Z7+AF7+AL7+AR7+AX7+BD7+BJ7 | BQ7: =IF(A7-Inputs!$B$30>=1,INDEX($BL$5:$BL$101,A7-Inputs!$B$30+1)*(1-Inputs!$B$29),0) | BR7: =BR6+BL7 | BS7: =BS6+BQ7 | BT7: =BR7*Inputs!$B$29 | BU7: =BR7*(1-Inputs!$B$29)-BS7 | BV7: =BP7+BU7 | BW7: =BM7+BN7+BO7+BQ7 | BX7: =BK7-BL7-BN7-BO7-BP7
A8: 3 | B8: =Inputs!$B$36+(Inputs!$B$37-Inputs!$B$36)*(1-EXP(-A8/Inputs!$B$38))+Inputs!$B$31/10000 | C8: =H7 | D8: =C8*Inputs!$B$33 | E8: =(C8-D8)*Inputs!$C$6/12 | F8: =IF(MAX(Inputs!$D$6-(A8-1),0)<=0,0,(C8-D8)*((Inputs!$C$6/12)/(1-(1+Inputs!$C$6/12)^(-MAX(Inputs!$D$6-(A8-1),0)))-Inputs!$C$6/12)) | G8: =(C8-D8-F8)*Inputs!$B$32 | H8: =C8-D8-F8-G8 | I8: =N7 | J8: =I8*Inputs!$B$33 | K8: =(I8-J8)*Inputs!$C$7/12 | L8: =IF(MAX(Inputs!$D$7-(A8-1),0)<=0,0,(I8-J8)*((Inputs!$C$7/12)/(1-(1+Inputs!$C$7/12)^(-MAX(Inputs!$D$7-(A8-1),0)))-Inputs!$C$7/12)) | M8: =(I8-J8-L8)*Inputs!$B$32 | N8: =I8-J8-L8-M8 | O8: =T7 | P8: =O8*Inputs!$B$33 | Q8: =(O8-P8)*Inputs!$C$8/12 | R8: =IF(MAX(Inputs!$D$8-(A8-1),0)<=0,0,(O8-P8)*((Inputs!$C$8/12)/(1-(1+Inputs!$C$8/12)^(-MAX(Inputs!$D$8-(A8-1),0)))-Inputs!$C$8/12)) | S8: =(O8-P8-R8)*Inputs!$B$32 | T8: =O8-P8-R8-S8 | U8: =Z7 | V8: =U8*Inputs!$B$33 | W8: =(U8-V8)*Inputs!$C$9/12 | X8: =IF(MAX(Inputs!$D$9-(A8-1),0)<=0,0,(U8-V8)*((Inputs!$C$9/12)/(1-(1+Inputs!$C$9/12)^(-MAX(Inputs!$D$9-(A8-1),0)))-Inputs!$C$9/12)) | Y8: =(U8-V8-X8)*Inputs!$B$32 | Z8: =U8-V8-X8-Y8 | AA8: =AF7 | AB8: =AA8*Inputs!$B$33 | AC8: =(AA8-AB8)*Inputs!$C$10/12 | AD8: =IF(MAX(Inputs!$D$10-(A8-1),0)<=0,0,(AA8-AB8)*((Inputs!$C$10/12)/(1-(1+Inputs!$C$10/12)^(-MAX(Inputs!$D$10-(A8-1),0)))-Inputs!$C$10/12)) | AE8: =(AA8-AB8-AD8)*Inputs!$B$32 | AF8: =AA8-AB8-AD8-AE8 | AG8: =AL7 | AH8: =AG8*Inputs!$B$33 | AI8: =(AG8-AH8)*Inputs!$C$11/12 | AJ8: =IF(MAX(Inputs!$D$11-(A8-1),0)<=0,0,(AG8-AH8)*((Inputs!$C$11/12)/(1-(1+Inputs!$C$11/12)^(-MAX(Inputs!$D$11-(A8-1),0)))-Inputs!$C$11/12)) | AK8: =(AG8-AH8-AJ8)*Inputs!$B$32 | AL8: =AG8-AH8-AJ8-AK8 | AM8: =AR7 | AN8: =AM8*Inputs!$B$33 | AO8: =(AM8-AN8)*Inputs!$C$12/12 | AP8: =IF(MAX(Inputs!$D$12-(A8-1),0)<=0,0,(AM8-AN8)*((Inputs!$C$12/12)/(1-(1+Inputs!$C$12/12)^(-MAX(Inputs!$D$12-(A8-1),0)))-Inputs!$C$12/12)) | AQ8: =(AM8-AN8-AP8)*Inputs!$B$32 | AR8: =AM8-AN8-AP8-AQ8 | AS8: =AX7 | AT8: =AS8*Inputs!$B$33 | AU8: =(AS8-AT8)*Inputs!$C$13/12 | AV8: =IF(MAX(Inputs!$D$13-(A8-1),0)<=0,0,(AS8-AT8)*((Inputs!$C$13/12)/(1-(1+Inputs!$C$13/12)^(-MAX(Inputs!$D$13-(A8-1),0)))-Inputs!$C$13/12)) | AW8: =(AS8-AT8-AV8)*Inputs!$B$32 | AX8: =AS8-AT8-AV8-AW8 | AY8: =BD7 | AZ8: =AY8*Inputs!$B$33 | BA8: =(AY8-AZ8)*Inputs!$C$14/12 | BB8: =IF(MAX(Inputs!$D$14-(A8-1),0)<=0,0,(AY8-AZ8)*((Inputs!$C$14/12)/(1-(1+Inputs!$C$14/12)^(-MAX(Inputs!$D$14-(A8-1),0)))-Inputs!$C$14/12)) | BC8: =(AY8-AZ8-BB8)*Inputs!$B$32 | BD8: =AY8-AZ8-BB8-BC8 | BE8: =BJ7 | BF8: =BE8*Inputs!$B$33 | BG8: =(BE8-BF8)*Inputs!$C$15/12 | BH8: =IF(MAX(Inputs!$D$15-(A8-1),0)<=0,0,(BE8-BF8)*((Inputs!$C$15/12)/(1-(1+Inputs!$C$15/12)^(-MAX(Inputs!$D$15-(A8-1),0)))-Inputs!$C$15/12)) | BI8: =(BE8-BF8-BH8)*Inputs!$B$32 | BJ8: =BE8-BF8-BH8-BI8 | BK8: =C8+I8+O8+U8+AA8+AG8+AM8+AS8+AY8+BE8 | BL8: =D8+J8+P8+V8+AB8+AH8+AN8+AT8+AZ8+BF8 | BM8: =E8+K8+Q8+W8+AC8+AI8+AO8+AU8+BA8+BG8 | BN8: =F8+L8+R8+X8+AD8+AJ8+AP8+AV8+BB8+BH8 | BO8: =G8+M8+S8+Y8+AE8+AK8+AQ8+AW8+BC8+BI8 | BP8: =H8+N8+T8+Z8+AF8+AL8+AR8+AX8+BD8+BJ8 | BQ8: =IF(A8-Inputs!$B$30>=1,INDEX($BL$5:$BL$101,A8-Inputs!$B$30+1)*(1-Inputs!$B$29),0) | BR8: =BR7+BL8 | BS8: =BS7+BQ8 | BT8: =BR8*Inputs!$B$29 | BU8: =BR8*(1-Inputs!$B$29)-BS8 | BV8: =BP8+BU8 | BW8: =BM8+BN8+BO8+BQ8 | BX8: =BK8-BL8-BN8-BO8-BP8
A9: 4 | B9: =Inputs!$B$36+(Inputs!$B$37-Inputs!$B$36)*(1-EXP(-A9/Inputs!$B$38))+Inputs!$B$31/10000 | C9: =H8 | D9: =C9*Inputs!$B$33 | E9: =(C9-D9)*Inputs!$C$6/12 | F9: =IF(MAX(Inputs!$D$6-(A9-1),0)<=0,0,(C9-D9)*((Inputs!$C$6/12)/(1-(1+Inputs!$C$6/12)^(-MAX(Inputs!$D$6-(A9-1),0)))-Inputs!$C$6/12)) | G9: =(C9-D9-F9)*Inputs!$B$32 | H9: =C9-D9-F9-G9 | I9: =N8 | J9: =I9*Inputs!$B$33 | K9: =(I9-J9)*Inputs!$C$7/12 | L9: =IF(MAX(Inputs!$D$7-(A9-1),0)<=0,0,(I9-J9)*((Inputs!$C$7/12)/(1-(1+Inputs!$C$7/12)^(-MAX(Inputs!$D$7-(A9-1),0)))-Inputs!$C$7/12)) | M9: =(I9-J9-L9)*Inputs!$B$32 | N9: =I9-J9-L9-M9 | O9: =T8 | P9: =O9*Inputs!$B$33 | Q9: =(O9-P9)*Inputs!$C$8/12 | R9: =IF(MAX(Inputs!$D$8-(A9-1),0)<=0,0,(O9-P9)*((Inputs!$C$8/12)/(1-(1+Inputs!$C$8/12)^(-MAX(Inputs!$D$8-(A9-1),0)))-Inputs!$C$8/12)) | S9: =(O9-P9-R9)*Inputs!$B$32 | T9: =O9-P9-R9-S9 | U9: =Z8 | V9: =U9*Inputs!$B$33 | W9: =(U9-V9)*Inputs!$C$9/12 | X9: =IF(MAX(Inputs!$D$9-(A9-1),0)<=0,0,(U9-V9)*((Inputs!$C$9/12)/(1-(1+Inputs!$C$9/12)^(-MAX(Inputs!$D$9-(A9-1),0)))-Inputs!$C$9/12)) | Y9: =(U9-V9-X9)*Inputs!$B$32 | Z9: =U9-V9-X9-Y9 | AA9: =AF8 | AB9: =AA9*Inputs!$B$33 | AC9: =(AA9-AB9)*Inputs!$C$10/12 | AD9: =IF(MAX(Inputs!$D$10-(A9-1),0)<=0,0,(AA9-AB9)*((Inputs!$C$10/12)/(1-(1+Inputs!$C$10/12)^(-MAX(Inputs!$D$10-(A9-1),0)))-Inputs!$C$10/12)) | AE9: =(AA9-AB9-AD9)*Inputs!$B$32 | AF9: =AA9-AB9-AD9-AE9 | AG9: =AL8 | AH9: =AG9*Inputs!$B$33 | AI9: =(AG9-AH9)*Inputs!$C$11/12 | AJ9: =IF(MAX(Inputs!$D$11-(A9-1),0)<=0,0,(AG9-AH9)*((Inputs!$C$11/12)/(1-(1+Inputs!$C$11/12)^(-MAX(Inputs!$D$11-(A9-1),0)))-Inputs!$C$11/12)) | AK9: =(AG9-AH9-AJ9)*Inputs!$B$32 | AL9: =AG9-AH9-AJ9-AK9 | AM9: =AR8 | AN9: =AM9*Inputs!$B$33 | AO9: =(AM9-AN9)*Inputs!$C$12/12 | AP9: =IF(MAX(Inputs!$D$12-(A9-1),0)<=0,0,(AM9-AN9)*((Inputs!$C$12/12)/(1-(1+Inputs!$C$12/12)^(-MAX(Inputs!$D$12-(A9-1),0)))-Inputs!$C$12/12)) | AQ9: =(AM9-AN9-AP9)*Inputs!$B$32 | AR9: =AM9-AN9-AP9-AQ9 | AS9: =AX8 | AT9: =AS9*Inputs!$B$33 | AU9: =(AS9-AT9)*Inputs!$C$13/12 | AV9: =IF(MAX(Inputs!$D$13-(A9-1),0)<=0,0,(AS9-AT9)*((Inputs!$C$13/12)/(1-(1+Inputs!$C$13/12)^(-MAX(Inputs!$D$13-(A9-1),0)))-Inputs!$C$13/12)) | AW9: =(AS9-AT9-AV9)*Inputs!$B$32 | AX9: =AS9-AT9-AV9-AW9 | AY9: =BD8 | AZ9: =AY9*Inputs!$B$33 | BA9: =(AY9-AZ9)*Inputs!$C$14/12 | BB9: =IF(MAX(Inputs!$D$14-(A9-1),0)<=0,0,(AY9-AZ9)*((Inputs!$C$14/12)/(1-(1+Inputs!$C$14/12)^(-MAX(Inputs!$D$14-(A9-1),0)))-Inputs!$C$14/12)) | BC9: =(AY9-AZ9-BB9)*Inputs!$B$32 | BD9: =AY9-AZ9-BB9-BC9 | BE9: =BJ8 | BF9: =BE9*Inputs!$B$33 | BG9: =(BE9-BF9)*Inputs!$C$15/12 | BH9: =IF(MAX(Inputs!$D$15-(A9-1),0)<=0,0,(BE9-BF9)*((Inputs!$C$15/12)/(1-(1+Inputs!$C$15/12)^(-MAX(Inputs!$D$15-(A9-1),0)))-Inputs!$C$15/12)) | BI9: =(BE9-BF9-BH9)*Inputs!$B$32 | BJ9: =BE9-BF9-BH9-BI9 | BK9: =C9+I9+O9+U9+AA9+AG9+AM9+AS9+AY9+BE9 | BL9: =D9+J9+P9+V9+AB9+AH9+AN9+AT9+AZ9+BF9 | BM9: =E9+K9+Q9+W9+AC9+AI9+AO9+AU9+BA9+BG9 | BN9: =F9+L9+R9+X9+AD9+AJ9+AP9+AV9+BB9+BH9 | BO9: =G9+M9+S9+Y9+AE9+AK9+AQ9+AW9+BC9+BI9 | BP9: =H9+N9+T9+Z9+AF9+AL9+AR9+AX9+BD9+BJ9 | BQ9: =IF(A9-Inputs!$B$30>=1,INDEX($BL$5:$BL$101,A9-Inputs!$B$30+1)*(1-Inputs!$B$29),0) | BR9: =BR8+BL9 | BS9: =BS8+BQ9 | BT9: =BR9*Inputs!$B$29 | BU9: =BR9*(1-Inputs!$B$29)-BS9 | BV9: =BP9+BU9 | BW9: =BM9+BN9+BO9+BQ9 | BX9: =BK9-BL9-BN9-BO9-BP9
A10: 5 | B10: =Inputs!$B$36+(Inputs!$B$37-Inputs!$B$36)*(1-EXP(-A10/Inputs!$B$38))+Inputs!$B$31/10000 | C10: =H9 | D10: =C10*Inputs!$B$33 | E10: =(C10-D10)*Inputs!$C$6/12 | F10: =IF(MAX(Inputs!$D$6-(A10-1),0)<=0,0,(C10-D10)*((Inputs!$C$6/12)/(1-(1+Inputs!$C$6/12)^(-MAX(Inputs!$D$6-(A10-1),0)))-Inputs!$C$6/12)) | G10: =(C10-D10-F10)*Inputs!$B$32 | H10: =C10-D10-F10-G10 | I10: =N9 | J10: =I10*Inputs!$B$33 | K10: =(I10-J10)*Inputs!$C$7/12 | L10: =IF(MAX(Inputs!$D$7-(A10-1),0)<=0,0,(I10-J10)*((Inputs!$C$7/12)/(1-(1+Inputs!$C$7/12)^(-MAX(Inputs!$D$7-(A10-1),0)))-Inputs!$C$7/12)) | M10: =(I10-J10-L10)*Inputs!$B$32 | N10: =I10-J10-L10-M10 | O10: =T9 | P10: =O10*Inputs!$B$33 | Q10: =(O10-P10)*Inputs!$C$8/12 | R10: =IF(MAX(Inputs!$D$8-(A10-1),0)<=0,0,(O10-P10)*((Inputs!$C$8/12)/(1-(1+Inputs!$C$8/12)^(-MAX(Inputs!$D$8-(A10-1),0)))-Inputs!$C$8/12)) | S10: =(O10-P10-R10)*Inputs!$B$32 | T10: =O10-P10-R10-S10 | U10: =Z9 | V10: =U10*Inputs!$B$33 | W10: =(U10-V10)*Inputs!$C$9/12 | X10: =IF(MAX(Inputs!$D$9-(A10-1),0)<=0,0,(U10-V10)*((Inputs!$C$9/12)/(1-(1+Inputs!$C$9/12)^(-MAX(Inputs!$D$9-(A10-1),0)))-Inputs!$C$9/12)) | Y10: =(U10-V10-X10)*Inputs!$B$32 | Z10: =U10-V10-X10-Y10 | AA10: =AF9 | AB10: =AA10*Inputs!$B$33 | AC10: =(AA10-AB10)*Inputs!$C$10/12 | AD10: =IF(MAX(Inputs!$D$10-(A10-1),0)<=0,0,(AA10-AB10)*((Inputs!$C$10/12)/(1-(1+Inputs!$C$10/12)^(-MAX(Inputs!$D$10-(A10-1),0)))-Inputs!$C$10/12)) | AE10: =(AA10-AB10-AD10)*Inputs!$B$32 | AF10: =AA10-AB10-AD10-AE10 | AG10: =AL9 | AH10: =AG10*Inputs!$B$33 | AI10: =(AG10-AH10)*Inputs!$C$11/12 | AJ10: =IF(MAX(Inputs!$D$11-(A10-1),0)<=0,0,(AG10-AH10)*((Inputs!$C$11/12)/(1-(1+Inputs!$C$11/12)^(-MAX(Inputs!$D$11-(A10-1),0)))-Inputs!$C$11/12)) | AK10: =(AG10-AH10-AJ10)*Inputs!$B$32 | AL10: =AG10-AH10-AJ10-AK10 | AM10: =AR9 | AN10: =AM10*Inputs!$B$33 | AO10: =(AM10-AN10)*Inputs!$C$12/12 | AP10: =IF(MAX(Inputs!$D$12-(A10-1),0)<=0,0,(AM10-AN10)*((Inputs!$C$12/12)/(1-(1+Inputs!$C$12/12)^(-MAX(Inputs!$D$12-(A10-1),0)))-Inputs!$C$12/12)) | AQ10: =(AM10-AN10-AP10)*Inputs!$B$32 | AR10: =AM10-AN10-AP10-AQ10 | AS10: =AX9 | AT10: =AS10*Inputs!$B$33 | AU10: =(AS10-AT10)*Inputs!$C$13/12 | AV10: =IF(MAX(Inputs!$D$13-(A10-1),0)<=0,0,(AS10-AT10)*((Inputs!$C$13/12)/(1-(1+Inputs!$C$13/12)^(-MAX(Inputs!$D$13-(A10-1),0)))-Inputs!$C$13/12)) | AW10: =(AS10-AT10-AV10)*Inputs!$B$32 | AX10: =AS10-AT10-AV10-AW10 | AY10: =BD9 | AZ10: =AY10*Inputs!$B$33 | BA10: =(AY10-AZ10)*Inputs!$C$14/12 | BB10: =IF(MAX(Inputs!$D$14-(A10-1),0)<=0,0,(AY10-AZ10)*((Inputs!$C$14/12)/(1-(1+Inputs!$C$14/12)^(-MAX(Inputs!$D$14-(A10-1),0)))-Inputs!$C$14/12)) | BC10: =(AY10-AZ10-BB10)*Inputs!$B$32 | BD10: =AY10-AZ10-BB10-BC10 | BE10: =BJ9 | BF10: =BE10*Inputs!$B$33 | BG10: =(BE10-BF10)*Inputs!$C$15/12 | BH10: =IF(MAX(Inputs!$D$15-(A10-1),0)<=0,0,(BE10-BF10)*((Inputs!$C$15/12)/(1-(1+Inputs!$C$15/12)^(-MAX(Inputs!$D$15-(A10-1),0)))-Inputs!$C$15/12)) | BI10: =(BE10-BF10-BH10)*Inputs!$B$32 | BJ10: =BE10-BF10-BH10-BI10 | BK10: =C10+I10+O10+U10+AA10+AG10+AM10+AS10+AY10+BE10 | BL10: =D10+J10+P10+V10+AB10+AH10+AN10+AT10+AZ10+BF10 | BM10: =E10+K10+Q10+W10+AC10+AI10+AO10+AU10+BA10+BG10 | BN10: =F10+L10+R10+X10+AD10+AJ10+AP10+AV10+BB10+BH10 | BO10: =G10+M10+S10+Y10+AE10+AK10+AQ10+AW10+BC10+BI10 | BP10: =H10+N10+T10+Z10+AF10+AL10+AR10+AX10+BD10+BJ10 | BQ10: =IF(A10-Inputs!$B$30>=1,INDEX($BL$5:$BL$101,A10-Inputs!$B$30+1)*(1-Inputs!$B$29),0) | BR10: =BR9+BL10 | BS10: =BS9+BQ10 | BT10: =BR10*Inputs!$B$29 | BU10: =BR10*(1-Inputs!$B$29)-BS10 | BV10: =BP10+BU10 | BW10: =BM10+BN10+BO10+BQ10 | BX10: =BK10-BL10-BN10-BO10-BP10
A11: 6 | B11: =Inputs!$B$36+(Inputs!$B$37-Inputs!$B$36)*(1-EXP(-A11/Inputs!$B$38))+Inputs!$B$31/10000 | C11: =H10 | D11: =C11*Inputs!$B$33 | E11: =(C11-D11)*Inputs!$C$6/12 | F11: =IF(MAX(Inputs!$D$6-(A11-1),0)<=0,0,(C11-D11)*((Inputs!$C$6/12)/(1-(1+Inputs!$C$6/12)^(-MAX(Inputs!$D$6-(A11-1),0)))-Inputs!$C$6/12)) | G11: =(C11-D11-F11)*Inputs!$B$32 | H11: =C11-D11-F11-G11 | I11: =N10 | J11: =I11*Inputs!$B$33 | K11: =(I11-J11)*Inputs!$C$7/12 | L11: =IF(MAX(Inputs!$D$7-(A11-1),0)<=0,0,(I11-J11)*((Inputs!$C$7/12)/(1-(1+Inputs!$C$7/12)^(-MAX(Inputs!$D$7-(A11-1),0)))-Inputs!$C$7/12)) | M11: =(I11-J11-L11)*Inputs!$B$32 | N11: =I11-J11-L11-M11 | O11: =T10 | P11: =O11*Inputs!$B$33 | Q11: =(O11-P11)*Inputs!$C$8/12 | R11: =IF(MAX(Inputs!$D$8-(A11-1),0)<=0,0,(O11-P11)*((Inputs!$C$8/12)/(1-(1+Inputs!$C$8/12)^(-MAX(Inputs!$D$8-(A11-1),0)))-Inputs!$C$8/12)) | S11: =(O11-P11-R11)*Inputs!$B$32 | T11: =O11-P11-R11-S11 | U11: =Z10 | V11: =U11*Inputs!$B$33 | W11: =(U11-V11)*Inputs!$C$9/12 | X11: =IF(MAX(Inputs!$D$9-(A11-1),0)<=0,0,(U11-V11)*((Inputs!$C$9/12)/(1-(1+Inputs!$C$9/12)^(-MAX(Inputs!$D$9-(A11-1),0)))-Inputs!$C$9/12)) | Y11: =(U11-V11-X11)*Inputs!$B$32 | Z11: =U11-V11-X11-Y11 | AA11: =AF10 | AB11: =AA11*Inputs!$B$33 | AC11: =(AA11-AB11)*Inputs!$C$10/12 | AD11: =IF(MAX(Inputs!$D$10-(A11-1),0)<=0,0,(AA11-AB11)*((Inputs!$C$10/12)/(1-(1+Inputs!$C$10/12)^(-MAX(Inputs!$D$10-(A11-1),0)))-Inputs!$C$10/12)) | AE11: =(AA11-AB11-AD11)*Inputs!$B$32 | AF11: =AA11-AB11-AD11-AE11 | AG11: =AL10 | AH11: =AG11*Inputs!$B$33 | AI11: =(AG11-AH11)*Inputs!$C$11/12 | AJ11: =IF(MAX(Inputs!$D$11-(A11-1),0)<=0,0,(AG11-AH11)*((Inputs!$C$11/12)/(1-(1+Inputs!$C$11/12)^(-MAX(Inputs!$D$11-(A11-1),0)))-Inputs!$C$11/12)) | AK11: =(AG11-AH11-AJ11)*Inputs!$B$32 | AL11: =AG11-AH11-AJ11-AK11 | AM11: =AR10 | AN11: =AM11*Inputs!$B$33 | AO11: =(AM11-AN11)*Inputs!$C$12/12 | AP11: =IF(MAX(Inputs!$D$12-(A11-1),0)<=0,0,(AM11-AN11)*((Inputs!$C$12/12)/(1-(1+Inputs!$C$12/12)^(-MAX(Inputs!$D$12-(A11-1),0)))-Inputs!$C$12/12)) | AQ11: =(AM11-AN11-AP11)*Inputs!$B$32 | AR11: =AM11-AN11-AP11-AQ11 | AS11: =AX10 | AT11: =AS11*Inputs!$B$33 | AU11: =(AS11-AT11)*Inputs!$C$13/12 | AV11: =IF(MAX(Inputs!$D$13-(A11-1),0)<=0,0,(AS11-AT11)*((Inputs!$C$13/12)/(1-(1+Inputs!$C$13/12)^(-MAX(Inputs!$D$13-(A11-1),0)))-Inputs!$C$13/12)) | AW11: =(AS11-AT11-AV11)*Inputs!$B$32 | AX11: =AS11-AT11-AV11-AW11 | AY11: =BD10 | AZ11: =AY11*Inputs!$B$33 | BA11: =(AY11-AZ11)*Inputs!$C$14/12 | BB11: =IF(MAX(Inputs!$D$14-(A11-1),0)<=0,0,(AY11-AZ11)*((Inputs!$C$14/12)/(1-(1+Inputs!$C$14/12)^(-MAX(Inputs!$D$14-(A11-1),0)))-Inputs!$C$14/12)) | BC11: =(AY11-AZ11-BB11)*Inputs!$B$32 | BD11: =AY11-AZ11-BB11-BC11 | BE11: =BJ10 | BF11: =BE11*Inputs!$B$33 | BG11: =(BE11-BF11)*Inputs!$C$15/12 | BH11: =IF(MAX(Inputs!$D$15-(A11-1),0)<=0,0,(BE11-BF11)*((Inputs!$C$15/12)/(1-(1+Inputs!$C$15/12)^(-MAX(Inputs!$D$15-(A11-1),0)))-Inputs!$C$15/12)) | BI11: =(BE11-BF11-BH11)*Inputs!$B$32 | BJ11: =BE11-BF11-BH11-BI11 | BK11: =C11+I11+O11+U11+AA11+AG11+AM11+AS11+AY11+BE11 | BL11: =D11+J11+P11+V11+AB11+AH11+AN11+AT11+AZ11+BF11 | BM11: =E11+K11+Q11+W11+AC11+AI11+AO11+AU11+BA11+BG11 | BN11: =F11+L11+R11+X11+AD11+AJ11+AP11+AV11+BB11+BH11 | BO11: =G11+M11+S11+Y11+AE11+AK11+AQ11+AW11+BC11+BI11 | BP11: =H11+N11+T11+Z11+AF11+AL11+AR11+AX11+BD11+BJ11 | BQ11: =IF(A11-Inputs!$B$30>=1,INDEX($BL$5:$BL$101,A11-Inputs!$B$30+1)*(1-Inputs!$B$29),0) | BR11: =BR10+BL11 | BS11: =BS10+BQ11 | BT11: =BR11*Inputs!$B$29 | BU11: =BR11*(1-Inputs!$B$29)-BS11 | BV11: =BP11+BU11 | BW11: =BM11+BN11+BO11+BQ11 | BX11: =BK11-BL11-BN11-BO11-BP11
A12: 7 | B12: =Inputs!$B$36+(Inputs!$B$37-Inputs!$B$36)*(1-EXP(-A12/Inputs!$B$38))+Inputs!$B$31/10000 | C12: =H11 | D12: =C12*Inputs!$B$33 | E12: =(C12-D12)*Inputs!$C$6/12 | F12: =IF(MAX(Inputs!$D$6-(A12-1),0)<=0,0,(C12-D12)*((Inputs!$C$6/12)/(1-(1+Inputs!$C$6/12)^(-MAX(Inputs!$D$6-(A12-1),0)))-Inputs!$C$6/12)) | G12: =(C12-D12-F12)*Inputs!$B$32 | H12: =C12-D12-F12-G12 | I12: =N11 | J12: =I12*Inputs!$B$33 | K12: =(I12-J12)*Inputs!$C$7/12 | L12: =IF(MAX(Inputs!$D$7-(A12-1),0)<=0,0,(I12-J12)*((Inputs!$C$7/12)/(1-(1+Inputs!$C$7/12)^(-MAX(Inputs!$D$7-(A12-1),0)))-Inputs!$C$7/12)) | M12: =(I12-J12-L12)*Inputs!$B$32 | N12: =I12-J12-L12-M12 | O12: =T11 | P12: =O12*Inputs!$B$33 | Q12: =(O12-P12)*Inputs!$C$8/12 | R12: =IF(MAX(Inputs!$D$8-(A12-1),0)<=0,0,(O12-P12)*((Inputs!$C$8/12)/(1-(1+Inputs!$C$8/12)^(-MAX(Inputs!$D$8-(A12-1),0)))-Inputs!$C$8/12)) | S12: =(O12-P12-R12)*Inputs!$B$32 | T12: =O12-P12-R12-S12 | U12: =Z11 | V12: =U12*Inputs!$B$33 | W12: =(U12-V12)*Inputs!$C$9/12 | X12: =IF(MAX(Inputs!$D$9-(A12-1),0)<=0,0,(U12-V12)*((Inputs!$C$9/12)/(1-(1+Inputs!$C$9/12)^(-MAX(Inputs!$D$9-(A12-1),0)))-Inputs!$C$9/12)) | Y12: =(U12-V12-X12)*Inputs!$B$32 | Z12: =U12-V12-X12-Y12 | AA12: =AF11 | AB12: =AA12*Inputs!$B$33 | AC12: =(AA12-AB12)*Inputs!$C$10/12 | AD12: =IF(MAX(Inputs!$D$10-(A12-1),0)<=0,0,(AA12-AB12)*((Inputs!$C$10/12)/(1-(1+Inputs!$C$10/12)^(-MAX(Inputs!$D$10-(A12-1),0)))-Inputs!$C$10/12)) | AE12: =(AA12-AB12-AD12)*Inputs!$B$32 | AF12: =AA12-AB12-AD12-AE12 | AG12: =AL11 | AH12: =AG12*Inputs!$B$33 | AI12: =(AG12-AH12)*Inputs!$C$11/12 | AJ12: =IF(MAX(Inputs!$D$11-(A12-1),0)<=0,0,(AG12-AH12)*((Inputs!$C$11/12)/(1-(1+Inputs!$C$11/12)^(-MAX(Inputs!$D$11-(A12-1),0)))-Inputs!$C$11/12)) | AK12: =(AG12-AH12-AJ12)*Inputs!$B$32 | AL12: =AG12-AH12-AJ12-AK12 | AM12: =AR11 | AN12: =AM12*Inputs!$B$33 | AO12: =(AM12-AN12)*Inputs!$C$12/12 | AP12: =IF(MAX(Inputs!$D$12-(A12-1),0)<=0,0,(AM12-AN12)*((Inputs!$C$12/12)/(1-(1+Inputs!$C$12/12)^(-MAX(Inputs!$D$12-(A12-1),0)))-Inputs!$C$12/12)) | AQ12: =(AM12-AN12-AP12)*Inputs!$B$32 | AR12: =AM12-AN12-AP12-AQ12 | AS12: =AX11 | AT12: =AS12*Inputs!$B$33 | AU12: =(AS12-AT12)*Inputs!$C$13/12 | AV12: =IF(MAX(Inputs!$D$13-(A12-1),0)<=0,0,(AS12-AT12)*((Inputs!$C$13/12)/(1-(1+Inputs!$C$13/12)^(-MAX(Inputs!$D$13-(A12-1),0)))-Inputs!$C$13/12)) | AW12: =(AS12-AT12-AV12)*Inputs!$B$32 | AX12: =AS12-AT12-AV12-AW12 | AY12: =BD11 | AZ12: =AY12*Inputs!$B$33 | BA12: =(AY12-AZ12)*Inputs!$C$14/12 | BB12: =IF(MAX(Inputs!$D$14-(A12-1),0)<=0,0,(AY12-AZ12)*((Inputs!$C$14/12)/(1-(1+Inputs!$C$14/12)^(-MAX(Inputs!$D$14-(A12-1),0)))-Inputs!$C$14/12)) | BC12: =(AY12-AZ12-BB12)*Inputs!$B$32 | BD12: =AY12-AZ12-BB12-BC12 | BE12: =BJ11 | BF12: =BE12*Inputs!$B$33 | BG12: =(BE12-BF12)*Inputs!$C$15/12 | BH12: =IF(MAX(Inputs!$D$15-(A12-1),0)<=0,0,(BE12-BF12)*((Inputs!$C$15/12)/(1-(1+Inputs!$C$15/12)^(-MAX(Inputs!$D$15-(A12-1),0)))-Inputs!$C$15/12)) | BI12: =(BE12-BF12-BH12)*Inputs!$B$32 | BJ12: =BE12-BF12-BH12-BI12 | BK12: =C12+I12+O12+U12+AA12+AG12+AM12+AS12+AY12+BE12 | BL12: =D12+J12+P12+V12+AB12+AH12+AN12+AT12+AZ12+BF12 | BM12: =E12+K12+Q12+W12+AC12+AI12+AO12+AU12+BA12+BG12 | BN12: =F12+L12+R12+X12+AD12+AJ12+AP12+AV12+BB12+BH12 | BO12: =G12+M12+S12+Y12+AE12+AK12+AQ12+AW12+BC12+BI12 | BP12: =H12+N12+T12+Z12+AF12+AL12+AR12+AX12+BD12+BJ12 | BQ12: =IF(A12-Inputs!$B$30>=1,INDEX($BL$5:$BL$101,A12-Inputs!$B$30+1)*(1-Inputs!$B$29),0) | BR12: =BR11+BL12 | BS12: =BS11+BQ12 | BT12: =BR12*Inputs!$B$29 | BU12: =BR12*(1-Inputs!$B$29)-BS12 | BV12: =BP12+BU12 | BW12: =BM12+BN12+BO12+BQ12 | BX12: =BK12-BL12-BN12-BO12-BP12
A13: 8 | B13: =Inputs!$B$36+(Inputs!$B$37-Inputs!$B$36)*(1-EXP(-A13/Inputs!$B$38))+Inputs!$B$31/10000 | C13: =H12 | D13: =C13*Inputs!$B$33 | E13: =(C13-D13)*Inputs!$C$6/12 | F13: =IF(MAX(Inputs!$D$6-(A13-1),0)<=0,0,(C13-D13)*((Inputs!$C$6/12)/(1-(1+Inputs!$C$6/12)^(-MAX(Inputs!$D$6-(A13-1),0)))-Inputs!$C$6/12)) | G13: =(C13-D13-F13)*Inputs!$B$32 | H13: =C13-D13-F13-G13 | I13: =N12 | J13: =I13*Inputs!$B$33 | K13: =(I13-J13)*Inputs!$C$7/12 | L13: =IF(MAX(Inputs!$D$7-(A13-1),0)<=0,0,(I13-J13)*((Inputs!$C$7/12)/(1-(1+Inputs!$C$7/12)^(-MAX(Inputs!$D$7-(A13-1),0)))-Inputs!$C$7/12)) | M13: =(I13-J13-L13)*Inputs!$B$32 | N13: =I13-J13-L13-M13 | O13: =T12 | P13: =O13*Inputs!$B$33 | Q13: =(O13-P13)*Inputs!$C$8/12 | R13: =IF(MAX(Inputs!$D$8-(A13-1),0)<=0,0,(O13-P13)*((Inputs!$C$8/12)/(1-(1+Inputs!$C$8/12)^(-MAX(Inputs!$D$8-(A13-1),0)))-Inputs!$C$8/12)) | S13: =(O13-P13-R13)*Inputs!$B$32 | T13: =O13-P13-R13-S13 | U13: =Z12 | V13: =U13*Inputs!$B$33 | W13: =(U13-V13)*Inputs!$C$9/12 | X13: =IF(MAX(Inputs!$D$9-(A13-1),0)<=0,0,(U13-V13)*((Inputs!$C$9/12)/(1-(1+Inputs!$C$9/12)^(-MAX(Inputs!$D$9-(A13-1),0)))-Inputs!$C$9/12)) | Y13: =(U13-V13-X13)*Inputs!$B$32 | Z13: =U13-V13-X13-Y13 | AA13: =AF12 | AB13: =AA13*Inputs!$B$33 | AC13: =(AA13-AB13)*Inputs!$C$10/12 | AD13: =IF(MAX(Inputs!$D$10-(A13-1),0)<=0,0,(AA13-AB13)*((Inputs!$C$10/12)/(1-(1+Inputs!$C$10/12)^(-MAX(Inputs!$D$10-(A13-1),0)))-Inputs!$C$10/12)) | AE13: =(AA13-AB13-AD13)*Inputs!$B$32 | AF13: =AA13-AB13-AD13-AE13 | AG13: =AL12 | AH13: =AG13*Inputs!$B$33 | AI13: =(AG13-AH13)*Inputs!$C$11/12 | AJ13: =IF(MAX(Inputs!$D$11-(A13-1),0)<=0,0,(AG13-AH13)*((Inputs!$C$11/12)/(1-(1+Inputs!$C$11/12)^(-MAX(Inputs!$D$11-(A13-1),0)))-Inputs!$C$11/12)) | AK13: =(AG13-AH13-AJ13)*Inputs!$B$32 | AL13: =AG13-AH13-AJ13-AK13 | AM13: =AR12 | AN13: =AM13*Inputs!$B$33 | AO13: =(AM13-AN13)*Inputs!$C$12/12 | AP13: =IF(MAX(Inputs!$D$12-(A13-1),0)<=0,0,(AM13-AN13)*((Inputs!$C$12/12)/(1-(1+Inputs!$C$12/12)^(-MAX(Inputs!$D$12-(A13-1),0)))-Inputs!$C$12/12)) | AQ13: =(AM13-AN13-AP13)*Inputs!$B$32 | AR13: =AM13-AN13-AP13-AQ13 | AS13: =AX12 | AT13: =AS13*Inputs!$B$33 | AU13: =(AS13-AT13)*Inputs!$C$13/12 | AV13: =IF(MAX(Inputs!$D$13-(A13-1),0)<=0,0,(AS13-AT13)*((Inputs!$C$13/12)/(1-(1+Inputs!$C$13/12)^(-MAX(Inputs!$D$13-(A13-1),0)))-Inputs!$C$13/12)) | AW13: =(AS13-AT13-AV13)*Inputs!$B$32 | AX13: =AS13-AT13-AV13-AW13 | AY13: =BD12 | AZ13: =AY13*Inputs!$B$33 | BA13: =(AY13-AZ13)*Inputs!$C$14/12 | BB13: =IF(MAX(Inputs!$D$14-(A13-1),0)<=0,0,(AY13-AZ13)*((Inputs!$C$14/12)/(1-(1+Inputs!$C$14/12)^(-MAX(Inputs!$D$14-(A13-1),0)))-Inputs!$C$14/12)) | BC13: =(AY13-AZ13-BB13)*Inputs!$B$32 | BD13: =AY13-AZ13-BB13-BC13 | BE13: =BJ12 | BF13: =BE13*Inputs!$B$33 | BG13: =(BE13-BF13)*Inputs!$C$15/12 | BH13: =IF(MAX(Inputs!$D$15-(A13-1),0)<=0,0,(BE13-BF13)*((Inputs!$C$15/12)/(1-(1+Inputs!$C$15/12)^(-MAX(Inputs!$D$15-(A13-1),0)))-Inputs!$C$15/12)) | BI13: =(BE13-BF13-BH13)*Inputs!$B$32 | BJ13: =BE13-BF13-BH13-BI13 | BK13: =C13+I13+O13+U13+AA13+AG13+AM13+AS13+AY13+BE13 | BL13: =D13+J13+P13+V13+AB13+AH13+AN13+AT13+AZ13+BF13 | BM13: =E13+K13+Q13+W13+AC13+AI13+AO13+AU13+BA13+BG13 | BN13: =F13+L13+R13+X13+AD13+AJ13+AP13+AV13+BB13+BH13 | BO13: =G13+M13+S13+Y13+AE13+AK13+AQ13+AW13+BC13+BI13 | BP13: =H13+N13+T13+Z13+AF13+AL13+AR13+AX13+BD13+BJ13 | BQ13: =IF(A13-Inputs!$B$30>=1,INDEX($BL$5:$BL$101,A13-Inputs!$B$30+1)*(1-Inputs!$B$29),0) | BR13: =BR12+BL13 | BS13: =BS12+BQ13 | BT13: =BR13*Inputs!$B$29 | BU13: =BR13*(1-Inputs!$B$29)-BS13 | BV13: =BP13+BU13 | BW13: =BM13+BN13+BO13+BQ13 | BX13: =BK13-BL13-BN13-BO13-BP13
A14: 9 | B14: =Inputs!$B$36+(Inputs!$B$37-Inputs!$B$36)*(1-EXP(-A14/Inputs!$B$38))+Inputs!$B$31/10000 | C14: =H13 | D14: =C14*Inputs!$B$33 | E14: =(C14-D14)*Inputs!$C$6/12 | F14: =IF(MAX(Inputs!$D$6-(A14-1),0)<=0,0,(C14-D14)*((Inputs!$C$6/12)/(1-(1+Inputs!$C$6/12)^(-MAX(Inputs!$D$6-(A14-1),0)))-Inputs!$C$6/12)) | G14: =(C14-D14-F14)*Inputs!$B$32 | H14: =C14-D14-F14-G14 | I14: =N13 | J14: =I14*Inputs!$B$33 | K14: =(I14-J14)*Inputs!$C$7/12 | L14: =IF(MAX(Inputs!$D$7-(A14-1),0)<=0,0,(I14-J14)*((Inputs!$C$7/12)/(1-(1+Inputs!$C$7/12)^(-MAX(Inputs!$D$7-(A14-1),0)))-Inputs!$C$7/12)) | M14: =(I14-J14-L14)*Inputs!$B$32 | N14: =I14-J14-L14-M14 | O14: =T13 | P14: =O14*Inputs!$B$33 | Q14: =(O14-P14)*Inputs!$C$8/12 | R14: =IF(MAX(Inputs!$D$8-(A14-1),0)<=0,0,(O14-P14)*((Inputs!$C$8/12)/(1-(1+Inputs!$C$8/12)^(-MAX(Inputs!$D$8-(A14-1),0)))-Inputs!$C$8/12)) | S14: =(O14-P14-R14)*Inputs!$B$32 | T14: =O14-P14-R14-S14 | U14: =Z13 | V14: =U14*Inputs!$B$33 | W14: =(U14-V14)*Inputs!$C$9/12 | X14: =IF(MAX(Inputs!$D$9-(A14-1),0)<=0,0,(U14-V14)*((Inputs!$C$9/12)/(1-(1+Inputs!$C$9/12)^(-MAX(Inputs!$D$9-(A14-1),0)))-Inputs!$C$9/12)) | Y14: =(U14-V14-X14)*Inputs!$B$32 | Z14: =U14-V14-X14-Y14 | AA14: =AF13 | AB14: =AA14*Inputs!$B$33 | AC14: =(AA14-AB14)*Inputs!$C$10/12 | AD14: =IF(MAX(Inputs!$D$10-(A14-1),0)<=0,0,(AA14-AB14)*((Inputs!$C$10/12)/(1-(1+Inputs!$C$10/12)^(-MAX(Inputs!$D$10-(A14-1),0)))-Inputs!$C$10/12)) | AE14: =(AA14-AB14-AD14)*Inputs!$B$32 | AF14: =AA14-AB14-AD14-AE14 | AG14: =AL13 | AH14: =AG14*Inputs!$B$33 | AI14: =(AG14-AH14)*Inputs!$C$11/12 | AJ14: =IF(MAX(Inputs!$D$11-(A14-1),0)<=0,0,(AG14-AH14)*((Inputs!$C$11/12)/(1-(1+Inputs!$C$11/12)^(-MAX(Inputs!$D$11-(A14-1),0)))-Inputs!$C$11/12)) | AK14: =(AG14-AH14-AJ14)*Inputs!$B$32 | AL14: =AG14-AH14-AJ14-AK14 | AM14: =AR13 | AN14: =AM14*Inputs!$B$33 | AO14: =(AM14-AN14)*Inputs!$C$12/12 | AP14: =IF(MAX(Inputs!$D$12-(A14-1),0)<=0,0,(AM14-AN14)*((Inputs!$C$12/12)/(1-(1+Inputs!$C$12/12)^(-MAX(Inputs!$D$12-(A14-1),0)))-Inputs!$C$12/12)) | AQ14: =(AM14-AN14-AP14)*Inputs!$B$32 | AR14: =AM14-AN14-AP14-AQ14 | AS14: =AX13 | AT14: =AS14*Inputs!$B$33 | AU14: =(AS14-AT14)*Inputs!$C$13/12 | AV14: =IF(MAX(Inputs!$D$13-(A14-1),0)<=0,0,(AS14-AT14)*((Inputs!$C$13/12)/(1-(1+Inputs!$C$13/12)^(-MAX(Inputs!$D$13-(A14-1),0)))-Inputs!$C$13/12)) | AW14: =(AS14-AT14-AV14)*Inputs!$B$32 | AX14: =AS14-AT14-AV14-AW14 | AY14: =BD13 | AZ14: =AY14*Inputs!$B$33 | BA14: =(AY14-AZ14)*Inputs!$C$14/12 | BB14: =IF(MAX(Inputs!$D$14-(A14-1),0)<=0,0,(AY14-AZ14)*((Inputs!$C$14/12)/(1-(1+Inputs!$C$14/12)^(-MAX(Inputs!$D$14-(A14-1),0)))-Inputs!$C$14/12)) | BC14: =(AY14-AZ14-BB14)*Inputs!$B$32 | BD14: =AY14-AZ14-BB14-BC14 | BE14: =BJ13 | BF14: =BE14*Inputs!$B$33 | BG14: =(BE14-BF14)*Inputs!$C$15/12 | BH14: =IF(MAX(Inputs!$D$15-(A14-1),0)<=0,0,(BE14-BF14)*((Inputs!$C$15/12)/(1-(1+Inputs!$C$15/12)^(-MAX(Inputs!$D$15-(A14-1),0)))-Inputs!$C$15/12)) | BI14: =(BE14-BF14-BH14)*Inputs!$B$32 | BJ14: =BE14-BF14-BH14-BI14 | BK14: =C14+I14+O14+U14+AA14+AG14+AM14+AS14+AY14+BE14 | BL14: =D14+J14+P14+V14+AB14+AH14+AN14+AT14+AZ14+BF14 | BM14: =E14+K14+Q14+W14+AC14+AI14+AO14+AU14+BA14+BG14 | BN14: =F14+L14+R14+X14+AD14+AJ14+AP14+AV14+BB14+BH14 | BO14: =G14+M14+S14+Y14+AE14+AK14+AQ14+AW14+BC14+BI14 | BP14: =H14+N14+T14+Z14+AF14+AL14+AR14+AX14+BD14+BJ14 | BQ14: =IF(A14-Inputs!$B$30>=1,INDEX($BL$5:$BL$101,A14-Inputs!$B$30+1)*(1-Inputs!$B$29),0) | BR14: =BR13+BL14 | BS14: =BS13+BQ14 | BT14: =BR14*Inputs!$B$29 | BU14: =BR14*(1-Inputs!$B$29)-BS14 | BV14: =BP14+BU14 | BW14: =BM14+BN14+BO14+BQ14 | BX14: =BK14-BL14-BN14-BO14-BP14
A15: 10 | B15: =Inputs!$B$36+(Inputs!$B$37-Inputs!$B$36)*(1-EXP(-A15/Inputs!$B$38))+Inputs!$B$31/10000 | C15: =H14 | D15: =C15*Inputs!$B$33 | E15: =(C15-D15)*Inputs!$C$6/12 | F15: =IF(MAX(Inputs!$D$6-(A15-1),0)<=0,0,(C15-D15)*((Inputs!$C$6/12)/(1-(1+Inputs!$C$6/12)^(-MAX(Inputs!$D$6-(A15-1),0)))-Inputs!$C$6/12)) | G15: =(C15-D15-F15)*Inputs!$B$32 | H15: =C15-D15-F15-G15 | I15: =N14 | J15: =I15*Inputs!$B$33 | K15: =(I15-J15)*Inputs!$C$7/12 | L15: =IF(MAX(Inputs!$D$7-(A15-1),0)<=0,0,(I15-J15)*((Inputs!$C$7/12)/(1-(1+Inputs!$C$7/12)^(-MAX(Inputs!$D$7-(A15-1),0)))-Inputs!$C$7/12)) | M15: =(I15-J15-L15)*Inputs!$B$32 | N15: =I15-J15-L15-M15 | O15: =T14 | P15: =O15*Inputs!$B$33 | Q15: =(O15-P15)*Inputs!$C$8/12 | R15: =IF(MAX(Inputs!$D$8-(A15-1),0)<=0,0,(O15-P15)*((Inputs!$C$8/12)/(1-(1+Inputs!$C$8/12)^(-MAX(Inputs!$D$8-(A15-1),0)))-Inputs!$C$8/12)) | S15: =(O15-P15-R15)*Inputs!$B$32 | T15: =O15-P15-R15-S15 | U15: =Z14 | V15: =U15*Inputs!$B$33 | W15: =(U15-V15)*Inputs!$C$9/12 | X15: =IF(MAX(Inputs!$D$9-(A15-1),0)<=0,0,(U15-V15)*((Inputs!$C$9/12)/(1-(1+Inputs!$C$9/12)^(-MAX(Inputs!$D$9-(A15-1),0)))-Inputs!$C$9/12)) | Y15: =(U15-V15-X15)*Inputs!$B$32 | Z15: =U15-V15-X15-Y15 | AA15: =AF14 | AB15: =AA15*Inputs!$B$33 | AC15: =(AA15-AB15)*Inputs!$C$10/12 | AD15: =IF(MAX(Inputs!$D$10-(A15-1),0)<=0,0,(AA15-AB15)*((Inputs!$C$10/12)/(1-(1+Inputs!$C$10/12)^(-MAX(Inputs!$D$10-(A15-1),0)))-Inputs!$C$10/12)) | AE15: =(AA15-AB15-AD15)*Inputs!$B$32 | AF15: =AA15-AB15-AD15-AE15 | AG15: =AL14 | AH15: =AG15*Inputs!$B$33 | AI15: =(AG15-AH15)*Inputs!$C$11/12 | AJ15: =IF(MAX(Inputs!$D$11-(A15-1),0)<=0,0,(AG15-AH15)*((Inputs!$C$11/12)/(1-(1+Inputs!$C$11/12)^(-MAX(Inputs!$D$11-(A15-1),0)))-Inputs!$C$11/12)) | AK15: =(AG15-AH15-AJ15)*Inputs!$B$32 | AL15: =AG15-AH15-AJ15-AK15 | AM15: =AR14 | AN15: =AM15*Inputs!$B$33 | AO15: =(AM15-AN15)*Inputs!$C$12/12 | AP15: =IF(MAX(Inputs!$D$12-(A15-1),0)<=0,0,(AM15-AN15)*((Inputs!$C$12/12)/(1-(1+Inputs!$C$12/12)^(-MAX(Inputs!$D$12-(A15-1),0)))-Inputs!$C$12/12)) | AQ15: =(AM15-AN15-AP15)*Inputs!$B$32 | AR15: =AM15-AN15-AP15-AQ15 | AS15: =AX14 | AT15: =AS15*Inputs!$B$33 | AU15: =(AS15-AT15)*Inputs!$C$13/12 | AV15: =IF(MAX(Inputs!$D$13-(A15-1),0)<=0,0,(AS15-AT15)*((Inputs!$C$13/12)/(1-(1+Inputs!$C$13/12)^(-MAX(Inputs!$D$13-(A15-1),0)))-Inputs!$C$13/12)) | AW15: =(AS15-AT15-AV15)*Inputs!$B$32 | AX15: =AS15-AT15-AV15-AW15 | AY15: =BD14 | AZ15: =AY15*Inputs!$B$33 | BA15: =(AY15-AZ15)*Inputs!$C$14/12 | BB15: =IF(MAX(Inputs!$D$14-(A15-1),0)<=0,0,(AY15-AZ15)*((Inputs!$C$14/12)/(1-(1+Inputs!$C$14/12)^(-MAX(Inputs!$D$14-(A15-1),0)))-Inputs!$C$14/12)) | BC15: =(AY15-AZ15-BB15)*Inputs!$B$32 | BD15: =AY15-AZ15-BB15-BC15 | BE15: =BJ14 | BF15: =BE15*Inputs!$B$33 | BG15: =(BE15-BF15)*Inputs!$C$15/12 | BH15: =IF(MAX(Inputs!$D$15-(A15-1),0)<=0,0,(BE15-BF15)*((Inputs!$C$15/12)/(1-(1+Inputs!$C$15/12)^(-MAX(Inputs!$D$15-(A15-1),0)))-Inputs!$C$15/12)) | BI15: =(BE15-BF15-BH15)*Inputs!$B$32 | BJ15: =BE15-BF15-BH15-BI15 | BK15: =C15+I15+O15+U15+AA15+AG15+AM15+AS15+AY15+BE15 | BL15: =D15+J15+P15+V15+AB15+AH15+AN15+AT15+AZ15+BF15 | BM15: =E15+K15+Q15+W15+AC15+AI15+AO15+AU15+BA15+BG15 | BN15: =F15+L15+R15+X15+AD15+AJ15+AP15+AV15+BB15+BH15 | BO15: =G15+M15+S15+Y15+AE15+AK15+AQ15+AW15+BC15+BI15 | BP15: =H15+N15+T15+Z15+AF15+AL15+AR15+AX15+BD15+BJ15 | BQ15: =IF(A15-Inputs!$B$30>=1,INDEX($BL$5:$BL$101,A15-Inputs!$B$30+1)*(1-Inputs!$B$29),0) | BR15: =BR14+BL15 | BS15: =BS14+BQ15 | BT15: =BR15*Inputs!$B$29 | BU15: =BR15*(1-Inputs!$B$29)-BS15 | BV15: =BP15+BU15 | BW15: =BM15+BN15+BO15+BQ15 | BX15: =BK15-BL15-BN15-BO15-BP15
A16: 11 | B16: =Inputs!$B$36+(Inputs!$B$37-Inputs!$B$36)*(1-EXP(-A16/Inputs!$B$38))+Inputs!$B$31/10000 | C16: =H15 | D16: =C16*Inputs!$B$33 | E16: =(C16-D16)*Inputs!$C$6/12 | F16: =IF(MAX(Inputs!$D$6-(A16-1),0)<=0,0,(C16-D16)*((Inputs!$C$6/12)/(1-(1+Inputs!$C$6/12)^(-MAX(Inputs!$D$6-(A16-1),0)))-Inputs!$C$6/12)) | G16: =(C16-D16-F16)*Inputs!$B$32 | H16: =C16-D16-F16-G16 | I16: =N15 | J16: =I16*Inputs!$B$33 | K16: =(I16-J16)*Inputs!$C$7/12 | L16: =IF(MAX(Inputs!$D$7-(A16-1),0)<=0,0,(I16-J16)*((Inputs!$C$7/12)/(1-(1+Inputs!$C$7/12)^(-MAX(Inputs!$D$7-(A16-1),0)))-Inputs!$C$7/12)) | M16: =(I16-J16-L16)*Inputs!$B$32 | N16: =I16-J16-L16-M16 | O16: =T15 | P16: =O16*Inputs!$B$33 | Q16: =(O16-P16)*Inputs!$C$8/12 | R16: =IF(MAX(Inputs!$D$8-(A16-1),0)<=0,0,(O16-P16)*((Inputs!$C$8/12)/(1-(1+Inputs!$C$8/12)^(-MAX(Inputs!$D$8-(A16-1),0)))-Inputs!$C$8/12)) | S16: =(O16-P16-R16)*Inputs!$B$32 | T16: =O16-P16-R16-S16 | U16: =Z15 | V16: =U16*Inputs!$B$33 | W16: =(U16-V16)*Inputs!$C$9/12 | X16: =IF(MAX(Inputs!$D$9-(A16-1),0)<=0,0,(U16-V16)*((Inputs!$C$9/12)/(1-(1+Inputs!$C$9/12)^(-MAX(Inputs!$D$9-(A16-1),0)))-Inputs!$C$9/12)) | Y16: =(U16-V16-X16)*Inputs!$B$32 | Z16: =U16-V16-X16-Y16 | AA16: =AF15 | AB16: =AA16*Inputs!$B$33 | AC16: =(AA16-AB16)*Inputs!$C$10/12 | AD16: =IF(MAX(Inputs!$D$10-(A16-1),0)<=0,0,(AA16-AB16)*((Inputs!$C$10/12)/(1-(1+Inputs!$C$10/12)^(-MAX(Inputs!$D$10-(A16-1),0)))-Inputs!$C$10/12)) | AE16: =(AA16-AB16-AD16)*Inputs!$B$32 | AF16: =AA16-AB16-AD16-AE16 | AG16: =AL15 | AH16: =AG16*Inputs!$B$33 | AI16: =(AG16-AH16)*Inputs!$C$11/12 | AJ16: =IF(MAX(Inputs!$D$11-(A16-1),0)<=0,0,(AG16-AH16)*((Inputs!$C$11/12)/(1-(1+Inputs!$C$11/12)^(-MAX(Inputs!$D$11-(A16-1),0)))-Inputs!$C$11/12)) | AK16: =(AG16-AH16-AJ16)*Inputs!$B$32 | AL16: =AG16-AH16-AJ16-AK16 | AM16: =AR15 | AN16: =AM16*Inputs!$B$33 | AO16: =(AM16-AN16)*Inputs!$C$12/12 | AP16: =IF(MAX(Inputs!$D$12-(A16-1),0)<=0,0,(AM16-AN16)*((Inputs!$C$12/12)/(1-(1+Inputs!$C$12/12)^(-MAX(Inputs!$D$12-(A16-1),0)))-Inputs!$C$12/12)) | AQ16: =(AM16-AN16-AP16)*Inputs!$B$32 | AR16: =AM16-AN16-AP16-AQ16 | AS16: =AX15 | AT16: =AS16*Inputs!$B$33 | AU16: =(AS16-AT16)*Inputs!$C$13/12 | AV16: =IF(MAX(Inputs!$D$13-(A16-1),0)<=0,0,(AS16-AT16)*((Inputs!$C$13/12)/(1-(1+Inputs!$C$13/12)^(-MAX(Inputs!$D$13-(A16-1),0)))-Inputs!$C$13/12)) | AW16: =(AS16-AT16-AV16)*Inputs!$B$32 | AX16: =AS16-AT16-AV16-AW16 | AY16: =BD15 | AZ16: =AY16*Inputs!$B$33 | BA16: =(AY16-AZ16)*Inputs!$C$14/12 | BB16: =IF(MAX(Inputs!$D$14-(A16-1),0)<=0,0,(AY16-AZ16)*((Inputs!$C$14/12)/(1-(1+Inputs!$C$14/12)^(-MAX(Inputs!$D$14-(A16-1),0)))-Inputs!$C$14/12)) | BC16: =(AY16-AZ16-BB16)*Inputs!$B$32 | BD16: =AY16-AZ16-BB16-BC16 | BE16: =BJ15 | BF16: =BE16*Inputs!$B$33 | BG16: =(BE16-BF16)*Inputs!$C$15/12 | BH16: =IF(MAX(Inputs!$D$15-(A16-1),0)<=0,0,(BE16-BF16)*((Inputs!$C$15/12)/(1-(1+Inputs!$C$15/12)^(-MAX(Inputs!$D$15-(A16-1),0)))-Inputs!$C$15/12)) | BI16: =(BE16-BF16-BH16)*Inputs!$B$32 | BJ16: =BE16-BF16-BH16-BI16 | BK16: =C16+I16+O16+U16+AA16+AG16+AM16+AS16+AY16+BE16 | BL16: =D16+J16+P16+V16+AB16+AH16+AN16+AT16+AZ16+BF16 | BM16: =E16+K16+Q16+W16+AC16+AI16+AO16+AU16+BA16+BG16 | BN16: =F16+L16+R16+X16+AD16+AJ16+AP16+AV16+BB16+BH16 | BO16: =G16+M16+S16+Y16+AE16+AK16+AQ16+AW16+BC16+BI16 | BP16: =H16+N16+T16+Z16+AF16+AL16+AR16+AX16+BD16+BJ16 | BQ16: =IF(A16-Inputs!$B$30>=1,INDEX($BL$5:$BL$101,A16-Inputs!$B$30+1)*(1-Inputs!$B$29),0) | BR16: =BR15+BL16 | BS16: =BS15+BQ16 | BT16: =BR16*Inputs!$B$29 | BU16: =BR16*(1-Inputs!$B$29)-BS16 | BV16: =BP16+BU16 | BW16: =BM16+BN16+BO16+BQ16 | BX16: =BK16-BL16-BN16-BO16-BP16
A17: 12 | B17: =Inputs!$B$36+(Inputs!$B$37-Inputs!$B$36)*(1-EXP(-A17/Inputs!$B$38))+Inputs!$B$31/10000 | C17: =H16 | D17: =C17*Inputs!$B$33 | E17: =(C17-D17)*Inputs!$C$6/12 | F17: =IF(MAX(Inputs!$D$6-(A17-1),0)<=0,0,(C17-D17)*((Inputs!$C$6/12)/(1-(1+Inputs!$C$6/12)^(-MAX(Inputs!$D$6-(A17-1),0)))-Inputs!$C$6/12)) | G17: =(C17-D17-F17)*Inputs!$B$32 | H17: =C17-D17-F17-G17 | I17: =N16 | J17: =I17*Inputs!$B$33 | K17: =(I17-J17)*Inputs!$C$7/12 | L17: =IF(MAX(Inputs!$D$7-(A17-1),0)<=0,0,(I17-J17)*((Inputs!$C$7/12)/(1-(1+Inputs!$C$7/12)^(-MAX(Inputs!$D$7-(A17-1),0)))-Inputs!$C$7/12)) | M17: =(I17-J17-L17)*Inputs!$B$32 | N17: =I17-J17-L17-M17 | O17: =T16 | P17: =O17*Inputs!$B$33 | Q17: =(O17-P17)*Inputs!$C$8/12 | R17: =IF(MAX(Inputs!$D$8-(A17-1),0)<=0,0,(O17-P17)*((Inputs!$C$8/12)/(1-(1+Inputs!$C$8/12)^(-MAX(Inputs!$D$8-(A17-1),0)))-Inputs!$C$8/12)) | S17: =(O17-P17-R17)*Inputs!$B$32 | T17: =O17-P17-R17-S17 | U17: =Z16 | V17: =U17*Inputs!$B$33 | W17: =(U17-V17)*Inputs!$C$9/12 | X17: =IF(MAX(Inputs!$D$9-(A17-1),0)<=0,0,(U17-V17)*((Inputs!$C$9/12)/(1-(1+Inputs!$C$9/12)^(-MAX(Inputs!$D$9-(A17-1),0)))-Inputs!$C$9/12)) | Y17: =(U17-V17-X17)*Inputs!$B$32 | Z17: =U17-V17-X17-Y17 | AA17: =AF16 | AB17: =AA17*Inputs!$B$33 | AC17: =(AA17-AB17)*Inputs!$C$10/12 | AD17: =IF(MAX(Inputs!$D$10-(A17-1),0)<=0,0,(AA17-AB17)*((Inputs!$C$10/12)/(1-(1+Inputs!$C$10/12)^(-MAX(Inputs!$D$10-(A17-1),0)))-Inputs!$C$10/12)) | AE17: =(AA17-AB17-AD17)*Inputs!$B$32 | AF17: =AA17-AB17-AD17-AE17 | AG17: =AL16 | AH17: =AG17*Inputs!$B$33 | AI17: =(AG17-AH17)*Inputs!$C$11/12 | AJ17: =IF(MAX(Inputs!$D$11-(A17-1),0)<=0,0,(AG17-AH17)*((Inputs!$C$11/12)/(1-(1+Inputs!$C$11/12)^(-MAX(Inputs!$D$11-(A17-1),0)))-Inputs!$C$11/12)) | AK17: =(AG17-AH17-AJ17)*Inputs!$B$32 | AL17: =AG17-AH17-AJ17-AK17 | AM17: =AR16 | AN17: =AM17*Inputs!$B$33 | AO17: =(AM17-AN17)*Inputs!$C$12/12 | AP17: =IF(MAX(Inputs!$D$12-(A17-1),0)<=0,0,(AM17-AN17)*((Inputs!$C$12/12)/(1-(1+Inputs!$C$12/12)^(-MAX(Inputs!$D$12-(A17-1),0)))-Inputs!$C$12/12)) | AQ17: =(AM17-AN17-AP17)*Inputs!$B$32 | AR17: =AM17-AN17-AP17-AQ17 | AS17: =AX16 | AT17: =AS17*Inputs!$B$33 | AU17: =(AS17-AT17)*Inputs!$C$13/12 | AV17: =IF(MAX(Inputs!$D$13-(A17-1),0)<=0,0,(AS17-AT17)*((Inputs!$C$13/12)/(1-(1+Inputs!$C$13/12)^(-MAX(Inputs!$D$13-(A17-1),0)))-Inputs!$C$13/12)) | AW17: =(AS17-AT17-AV17)*Inputs!$B$32 | AX17: =AS17-AT17-AV17-AW17 | AY17: =BD16 | AZ17: =AY17*Inputs!$B$33 | BA17: =(AY17-AZ17)*Inputs!$C$14/12 | BB17: =IF(MAX(Inputs!$D$14-(A17-1),0)<=0,0,(AY17-AZ17)*((Inputs!$C$14/12)/(1-(1+Inputs!$C$14/12)^(-MAX(Inputs!$D$14-(A17-1),0)))-Inputs!$C$14/12)) | BC17: =(AY17-AZ17-BB17)*Inputs!$B$32 | BD17: =AY17-AZ17-BB17-BC17 | BE17: =BJ16 | BF17: =BE17*Inputs!$B$33 | BG17: =(BE17-BF17)*Inputs!$C$15/12 | BH17: =IF(MAX(Inputs!$D$15-(A17-1),0)<=0,0,(BE17-BF17)*((Inputs!$C$15/12)/(1-(1+Inputs!$C$15/12)^(-MAX(Inputs!$D$15-(A17-1),0)))-Inputs!$C$15/12)) | BI17: =(BE17-BF17-BH17)*Inputs!$B$32 | BJ17: =BE17-BF17-BH17-BI17 | BK17: =C17+I17+O17+U17+AA17+AG17+AM17+AS17+AY17+BE17 | BL17: =D17+J17+P17+V17+AB17+AH17+AN17+AT17+AZ17+BF17 | BM17: =E17+K17+Q17+W17+AC17+AI17+AO17+AU17+BA17+BG17 | BN17: =F17+L17+R17+X17+AD17+AJ17+AP17+AV17+BB17+BH17 | BO17: =G17+M17+S17+Y17+AE17+AK17+AQ17+AW17+BC17+BI17 | BP17: =H17+N17+T17+Z17+AF17+AL17+AR17+AX17+BD17+BJ17 | BQ17: =IF(A17-Inputs!$B$30>=1,INDEX($BL$5:$BL$101,A17-Inputs!$B$30+1)*(1-Inputs!$B$29),0) | BR17: =BR16+BL17 | BS17: =BS16+BQ17 | BT17: =BR17*Inputs!$B$29 | BU17: =BR17*(1-Inputs!$B$29)-BS17 | BV17: =BP17+BU17 | BW17: =BM17+BN17+BO17+BQ17 | BX17: =BK17-BL17-BN17-BO17-BP17
... A101: 96 | B101: =Inputs!$B$36+(Inputs!$B$37-Inputs!$B$36)*(1-EXP(-A101/Inputs!$B$38))+Inputs!$B$31/10000 | C101: =H100 | D101: =C101*Inputs!$B$33 | E101: =(C101-D101)*Inputs!$C$6/12 | F101: =IF(MAX(Inputs!$D$6-(A101-1),0)<=0,0,(C101-D101)*((Inputs!$C$6/12)/(1-(1+Inputs!$C$6/12)^(-MAX(Inputs!$D$6-(A101-1),0)))-Inputs!$C$6/12)) | G101: =(C101-D101-F101)*Inputs!$B$32 | H101: =C101-D101-F101-G101 | I101: =N100 | J101: =I101*Inputs!$B$33 | K101: =(I101-J101)*Inputs!$C$7/12 | L101: =IF(MAX(Inputs!$D$7-(A101-1),0)<=0,0,(I101-J101)*((Inputs!$C$7/12)/(1-(1+Inputs!$C$7/12)^(-MAX(Inputs!$D$7-(A101-1),0)))-Inputs!$C$7/12)) | M101: =(I101-J101-L101)*Inputs!$B$32 | N101: =I101-J101-L101-M101 | O101: =T100 | P101: =O101*Inputs!$B$33 | Q101: =(O101-P101)*Inputs!$C$8/12 | R101: =IF(MAX(Inputs!$D$8-(A101-1),0)<=0,0,(O101-P101)*((Inputs!$C$8/12)/(1-(1+Inputs!$C$8/12)^(-MAX(Inputs!$D$8-(A101-1),0)))-Inputs!$C$8/12)) | S101: =(O101-P101-R101)*Inputs!$B$32 | T101: =O101-P101-R101-S101 | U101: =Z100 | V101: =U101*Inputs!$B$33 | W101: =(U101-V101)*Inputs!$C$9/12 | X101: =IF(MAX(Inputs!$D$9-(A101-1),0)<=0,0,(U101-V101)*((Inputs!$C$9/12)/(1-(1+Inputs!$C$9/12)^(-MAX(Inputs!$D$9-(A101-1),0)))-Inputs!$C$9/12)) | Y101: =(U101-V101-X101)*Inputs!$B$32 | Z101: =U101-V101-X101-Y101 | AA101: =AF100 | AB101: =AA101*Inputs!$B$33 | AC101: =(AA101-AB101)*Inputs!$C$10/12 | AD101: =IF(MAX(Inputs!$D$10-(A101-1),0)<=0,0,(AA101-AB101)*((Inputs!$C$10/12)/(1-(1+Inputs!$C$10/12)^(-MAX(Inputs!$D$10-(A101-1),0)))-Inputs!$C$10/12)) | AE101: =(AA101-AB101-AD101)*Inputs!$B$32 | AF101: =AA101-AB101-AD101-AE101 | AG101: =AL100 | AH101: =AG101*Inputs!$B$33 | AI101: =(AG101-AH101)*Inputs!$C$11/12 | AJ101: =IF(MAX(Inputs!$D$11-(A101-1),0)<=0,0,(AG101-AH101)*((Inputs!$C$11/12)/(1-(1+Inputs!$C$11/12)^(-MAX(Inputs!$D$11-(A101-1),0)))-Inputs!$C$11/12)) | AK101: =(AG101-AH101-AJ101)*Inputs!$B$32 | AL101: =AG101-AH101-AJ101-AK101 | AM101: =AR100 | AN101: =AM101*Inputs!$B$33 | AO101: =(AM101-AN101)*Inputs!$C$12/12 | AP101: =IF(MAX(Inputs!$D$12-(A101-1),0)<=0,0,(AM101-AN101)*((Inputs!$C$12/12)/(1-(1+Inputs!$C$12/12)^(-MAX(Inputs!$D$12-(A101-1),0)))-Inputs!$C$12/12)) | AQ101: =(AM101-AN101-AP101)*Inputs!$B$32 | AR101: =AM101-AN101-AP101-AQ101 | AS101: =AX100 | AT101: =AS101*Inputs!$B$33 | AU101: =(AS101-AT101)*Inputs!$C$13/12 | AV101: =IF(MAX(Inputs!$D$13-(A101-1),0)<=0,0,(AS101-AT101)*((Inputs!$C$13/12)/(1-(1+Inputs!$C$13/12)^(-MAX(Inputs!$D$13-(A101-1),0)))-Inputs!$C$13/12)) | AW101: =(AS101-AT101-AV101)*Inputs!$B$32 | AX101: =AS101-AT101-AV101-AW101 | AY101: =BD100 | AZ101: =AY101*Inputs!$B$33 | BA101: =(AY101-AZ101)*Inputs!$C$14/12 | BB101: =IF(MAX(Inputs!$D$14-(A101-1),0)<=0,0,(AY101-AZ101)*((Inputs!$C$14/12)/(1-(1+Inputs!$C$14/12)^(-MAX(Inputs!$D$14-(A101-1),0)))-Inputs!$C$14/12)) | BC101: =(AY101-AZ101-BB101)*Inputs!$B$32 | BD101: =AY101-AZ101-BB101-BC101 | BE101: =BJ100 | BF101: =BE101*Inputs!$B$33 | BG101: =(BE101-BF101)*Inputs!$C$15/12 | BH101: =IF(MAX(Inputs!$D$15-(A101-1),0)<=0,0,(BE101-BF101)*((Inputs!$C$15/12)/(1-(1+Inputs!$C$15/12)^(-MAX(Inputs!$D$15-(A101-1),0)))-Inputs!$C$15/12)) | BI101: =(BE101-BF101-BH101)*Inputs!$B$32 | BJ101: =BE101-BF101-BH101-BI101 | BK101: =C101+I101+O101+U101+AA101+AG101+AM101+AS101+AY101+BE101 | BL101: =D101+J101+P101+V101+AB101+AH101+AN101+AT101+AZ101+BF101 | BM101: =E101+K101+Q101+W101+AC101+AI101+AO101+AU101+BA101+BG101 | BN101: =F101+L101+R101+X101+AD101+AJ101+AP101+AV101+BB101+BH101 | BO101: =G101+M101+S101+Y101+AE101+AK101+AQ101+AW101+BC101+BI101 | BP101: =H101+N101+T101+Z101+AF101+AL101+AR101+AX101+BD101+BJ101 | BQ101: =IF(A101-Inputs!$B$30>=1,INDEX($BL$5:$BL$101,A101-Inputs!$B$30+1)*(1-Inputs!$B$29),0) | BR101: =BR100+BL101 | BS101: =BS100+BQ101 | BT101: =BR101*Inputs!$B$29 | BU101: =BR101*(1-Inputs!$B$29)-BS101 | BV101: =BP101+BU101 | BW101: =BM101+BN101+BO101+BQ101 | BX101: =BK101-BL101-BN101-BO101-BP101

Sheet Waterfall
A1: Waterfall
A2: Interest and principal priority of payments, turbo, reserve, write-downs.
A4: Period | B4: Senior fees accrued | C4: Senior fees due | D4: A beg balance | E4: B beg balance | F4: C beg balance | G4: A coupon | H4: B coupon | I4: C coupon | J4: A interest accrued | K4: A interest due (incl carry) | L4: B interest accrued | M4: B interest due (incl carry) | N4: C interest accrued | O4: C interest due (incl carry) | P4: Interest collections | Q4: Reserve beg | R4: Reserve draw | S4: Available interest funds | T4: Available principal funds | U4: Sequential flag | V4: Sum A+B+C beg | W4: A regular principal | X4: B regular principal | Y4: C regular principal | Z4: Principal to residual | AA4: A pro forma balance | AB4: B pro forma balance | AC4: C pro forma balance | AD4: Pro forma A+B+C | AE4: 1 Senior fees paid | AF4: Remaining after fees | AG4: 2 A interest paid | AH4: Remaining after A int | AI4: 3 Turbo (A test breach) | AJ4: Remaining after turbo 1 | AK4: 4 B interest paid | AL4: Remaining after B int | AM4: 5 Turbo (B test breach) | AN4: Remaining after turbo 2 | AO4: 6 C interest paid | AP4: Remaining after C int | AQ4: 7 Turbo (C test breach) | AR4: Remaining after turbo 3 | AS4: Deficiency before turbo 4 | AT4: 8 Turbo (cure deficiency) | AU4: Remaining after turbo 4 | AV4: Turbo total | AW4: Turbo to A | AX4: Turbo to B | AY4: Turbo to C | AZ4: A after turbo | BA4: B after turbo | BB4: C after turbo | BC4: A+B+C after turbo | BD4: Principal deficiency | BE4: C write-down | BF4: B write-down | BG4: A write-down | BH4: A end balance | BI4: B end balance | BJ4: C end balance | BK4: Notes retired flag | BL4: Reserve after draw | BM4: 9 Reserve top-up | BN4: Reserve release | BO4: Reserve end | BP4: 10 Residual interest distribution | BQ4: Residual cash (int + prin + release) | BR4: A principal paid | BS4: B principal paid | BT4: C principal paid | BU4: Notes P+I paid | BV4: A interest shortfall carried | BW4: B interest shortfall carried | BX4: C interest shortfall carried | BY4: Fee shortfall carried | BZ4: Cash conservation check
A5: 0 | BH5: =Inputs!$B$39 | BI5: =Inputs!$B$40 | BJ5: =Inputs!$B$41 | BO5: =Inputs!$B$47 | BV5: 0 | BW5: 0 | BX5: 0 | BY5: 0
A6: 1 | B6: =Inputs!$B$51/12*Pool!BK6 | C6: =B6+BY5 | D6: =BH5 | E6: =BI5 | F6: =BJ5 | G6: =MAX(0,Pool!B6+Inputs!$B$42) | H6: =MAX(0,Pool!B6+Inputs!$B$43) | I6: =Inputs!$B$44 | J6: =D6*G6/12 | K6: =J6+BV5 | L6: =E6*H6/12 | M6: =L6+BW5 | N6: =F6*I6/12 | O6: =N6+BX5 | P6: =Pool!BM6 | Q6: =BO5 | R6: =MIN(Q6,MAX(0,C6+K6+M6-P6)) | S6: =P6+R6 | T6: =Pool!BN6+Pool!BO6+Pool!BQ6 | U6: =IF(OR(Inputs!$B$53=1,Tests!M5=1),1,0) | V6: =D6+E6+F6 | W6: =IF(U6=1,MIN(D6,T6),IF(V6<=0,0,MIN(T6,V6)*D6/V6)) | X6: =IF(U6=1,MIN(E6,T6-W6),IF(V6<=0,0,MIN(T6,V6)*E6/V6)) | Y6: =IF(U6=1,MIN(F6,T6-W6-X6),IF(V6<=0,0,MIN(T6,V6)*F6/V6)) | Z6: =T6-W6-X6-Y6 | AA6: =D6-W6 | AB6: =E6-X6 | AC6: =F6-Y6 | AD6: =AA6+AB6+AC6 | AE6: =MIN(C6,S6) | AF6: =S6-AE6 | AG6: =MIN(K6,AF6) | AH6: =AF6-AG6 | AI6: =IF(Tests!F6=1,MIN(AH6,AD6),0) | AJ6: =AH6-AI6 | AK6: =MIN(M6,AJ6) | AL6: =AJ6-AK6 | AM6: =IF(Tests!I6=1,MIN(AL6,AD6-AI6),0) | AN6: =AL6-AM6 | AO6: =MIN(O6,AN6) | AP6: =AN6-AO6 | AQ6: =IF(Tests!L6=1,MIN(AP6,AD6-AI6-AM6),0) | AR6: =AP6-AQ6 | AS6: =MAX(0,AD6-AI6-AM6-AQ6-Pool!BV6) | AT6: =MIN(AR6,AS6) | AU6: =AR6-AT6 | AV6: =AI6+AM6+AQ6+AT6 | AW6: =MIN(AA6,AV6) | AX6: =MIN(AB6,AV6-AW6) | AY6: =MIN(AC6,AV6-AW6-AX6) | AZ6: =AA6-AW6 | BA6: =AB6-AX6 | BB6: =AC6-AY6 | BC6: =AZ6+BA6+BB6 | BD6: =MAX(0,BC6-Pool!BV6) | BE6: =MIN(BB6,BD6) | BF6: =MIN(BA6,BD6-BE6) | BG6: =MIN(AZ6,BD6-BE6-BF6) | BH6: =AZ6-BG6 | BI6: =BA6-BF6 | BJ6: =BB6-BE6 | BK6: =IF(BH6+BI6+BJ6<0.005,1,0) | BL6: =Q6-R6 | BM6: =IF(BK6=1,0,MIN(AU6,MAX(0,Inputs!$B$48-BL6))) | BN6: =IF(BK6=1,BL6,0) | BO6: =BL6+BM6-BN6 | BP6: =AU6-BM6 | BQ6: =BP6+Z6+BN6 | BR6: =W6+AW6 | BS6: =X6+AX6 | BT6: =Y6+AY6 | BU6: =AG6+AK6+AO6+BR6+BS6+BT6 | BV6: =K6-AG6 | BW6: =M6-AK6 | BX6: =O6-AO6 | BY6: =C6-AE6 | BZ6: =AE6+BU6+BQ6+(BO6-Q6)-Pool!BW6
A7: 2 | B7: =Inputs!$B$51/12*Pool!BK7 | C7: =B7+BY6 | D7: =BH6 | E7: =BI6 | F7: =BJ6 | G7: =MAX(0,Pool!B7+Inputs!$B$42) | H7: =MAX(0,Pool!B7+Inputs!$B$43) | I7: =Inputs!$B$44 | J7: =D7*G7/12 | K7: =J7+BV6 | L7: =E7*H7/12 | M7: =L7+BW6 | N7: =F7*I7/12 | O7: =N7+BX6 | P7: =Pool!BM7 | Q7: =BO6 | R7: =MIN(Q7,MAX(0,C7+K7+M7-P7)) | S7: =P7+R7 | T7: =Pool!BN7+Pool!BO7+Pool!BQ7 | U7: =IF(OR(Inputs!$B$53=1,Tests!M6=1),1,0) | V7: =D7+E7+F7 | W7: =IF(U7=1,MIN(D7,T7),IF(V7<=0,0,MIN(T7,V7)*D7/V7)) | X7: =IF(U7=1,MIN(E7,T7-W7),IF(V7<=0,0,MIN(T7,V7)*E7/V7)) | Y7: =IF(U7=1,MIN(F7,T7-W7-X7),IF(V7<=0,0,MIN(T7,V7)*F7/V7)) | Z7: =T7-W7-X7-Y7 | AA7: =D7-W7 | AB7: =E7-X7 | AC7: =F7-Y7 | AD7: =AA7+AB7+AC7 | AE7: =MIN(C7,S7) | AF7: =S7-AE7 | AG7: =MIN(K7,AF7) | AH7: =AF7-AG7 | AI7: =IF(Tests!F7=1,MIN(AH7,AD7),0) | AJ7: =AH7-AI7 | AK7: =MIN(M7,AJ7) | AL7: =AJ7-AK7 | AM7: =IF(Tests!I7=1,MIN(AL7,AD7-AI7),0) | AN7: =AL7-AM7 | AO7: =MIN(O7,AN7) | AP7: =AN7-AO7 | AQ7: =IF(Tests!L7=1,MIN(AP7,AD7-AI7-AM7),0) | AR7: =AP7-AQ7 | AS7: =MAX(0,AD7-AI7-AM7-AQ7-Pool!BV7) | AT7: =MIN(AR7,AS7) | AU7: =AR7-AT7 | AV7: =AI7+AM7+AQ7+AT7 | AW7: =MIN(AA7,AV7) | AX7: =MIN(AB7,AV7-AW7) | AY7: =MIN(AC7,AV7-AW7-AX7) | AZ7: =AA7-AW7 | BA7: =AB7-AX7 | BB7: =AC7-AY7 | BC7: =AZ7+BA7+BB7 | BD7: =MAX(0,BC7-Pool!BV7) | BE7: =MIN(BB7,BD7) | BF7: =MIN(BA7,BD7-BE7) | BG7: =MIN(AZ7,BD7-BE7-BF7) | BH7: =AZ7-BG7 | BI7: =BA7-BF7 | BJ7: =BB7-BE7 | BK7: =IF(BH7+BI7+BJ7<0.005,1,0) | BL7: =Q7-R7 | BM7: =IF(BK7=1,0,MIN(AU7,MAX(0,Inputs!$B$48-BL7))) | BN7: =IF(BK7=1,BL7,0) | BO7: =BL7+BM7-BN7 | BP7: =AU7-BM7 | BQ7: =BP7+Z7+BN7 | BR7: =W7+AW7 | BS7: =X7+AX7 | BT7: =Y7+AY7 | BU7: =AG7+AK7+AO7+BR7+BS7+BT7 | BV7: =K7-AG7 | BW7: =M7-AK7 | BX7: =O7-AO7 | BY7: =C7-AE7 | BZ7: =AE7+BU7+BQ7+(BO7-Q7)-Pool!BW7
A8: 3 | B8: =Inputs!$B$51/12*Pool!BK8 | C8: =B8+BY7 | D8: =BH7 | E8: =BI7 | F8: =BJ7 | G8: =MAX(0,Pool!B8+Inputs!$B$42) | H8: =MAX(0,Pool!B8+Inputs!$B$43) | I8: =Inputs!$B$44 | J8: =D8*G8/12 | K8: =J8+BV7 | L8: =E8*H8/12 | M8: =L8+BW7 | N8: =F8*I8/12 | O8: =N8+BX7 | P8: =Pool!BM8 | Q8: =BO7 | R8: =MIN(Q8,MAX(0,C8+K8+M8-P8)) | S8: =P8+R8 | T8: =Pool!BN8+Pool!BO8+Pool!BQ8 | U8: =IF(OR(Inputs!$B$53=1,Tests!M7=1),1,0) | V8: =D8+E8+F8 | W8: =IF(U8=1,MIN(D8,T8),IF(V8<=0,0,MIN(T8,V8)*D8/V8)) | X8: =IF(U8=1,MIN(E8,T8-W8),IF(V8<=0,0,MIN(T8,V8)*E8/V8)) | Y8: =IF(U8=1,MIN(F8,T8-W8-X8),IF(V8<=0,0,MIN(T8,V8)*F8/V8)) | Z8: =T8-W8-X8-Y8 | AA8: =D8-W8 | AB8: =E8-X8 | AC8: =F8-Y8 | AD8: =AA8+AB8+AC8 | AE8: =MIN(C8,S8) | AF8: =S8-AE8 | AG8: =MIN(K8,AF8) | AH8: =AF8-AG8 | AI8: =IF(Tests!F8=1,MIN(AH8,AD8),0) | AJ8: =AH8-AI8 | AK8: =MIN(M8,AJ8) | AL8: =AJ8-AK8 | AM8: =IF(Tests!I8=1,MIN(AL8,AD8-AI8),0) | AN8: =AL8-AM8 | AO8: =MIN(O8,AN8) | AP8: =AN8-AO8 | AQ8: =IF(Tests!L8=1,MIN(AP8,AD8-AI8-AM8),0) | AR8: =AP8-AQ8 | AS8: =MAX(0,AD8-AI8-AM8-AQ8-Pool!BV8) | AT8: =MIN(AR8,AS8) | AU8: =AR8-AT8 | AV8: =AI8+AM8+AQ8+AT8 | AW8: =MIN(AA8,AV8) | AX8: =MIN(AB8,AV8-AW8) | AY8: =MIN(AC8,AV8-AW8-AX8) | AZ8: =AA8-AW8 | BA8: =AB8-AX8 | BB8: =AC8-AY8 | BC8: =AZ8+BA8+BB8 | BD8: =MAX(0,BC8-Pool!BV8) | BE8: =MIN(BB8,BD8) | BF8: =MIN(BA8,BD8-BE8) | BG8: =MIN(AZ8,BD8-BE8-BF8) | BH8: =AZ8-BG8 | BI8: =BA8-BF8 | BJ8: =BB8-BE8 | BK8: =IF(BH8+BI8+BJ8<0.005,1,0) | BL8: =Q8-R8 | BM8: =IF(BK8=1,0,MIN(AU8,MAX(0,Inputs!$B$48-BL8))) | BN8: =IF(BK8=1,BL8,0) | BO8: =BL8+BM8-BN8 | BP8: =AU8-BM8 | BQ8: =BP8+Z8+BN8 | BR8: =W8+AW8 | BS8: =X8+AX8 | BT8: =Y8+AY8 | BU8: =AG8+AK8+AO8+BR8+BS8+BT8 | BV8: =K8-AG8 | BW8: =M8-AK8 | BX8: =O8-AO8 | BY8: =C8-AE8 | BZ8: =AE8+BU8+BQ8+(BO8-Q8)-Pool!BW8
